Workbook

Sheet Players
A1: Player Name | B1: Position | C1: Team | D1: Cost | E1: Start | F1: Score | G1: Score 2+ | H1: Score 3+ | I1: Assist | J1: Yellow Card | K1: Clean Sheet | L1: Concede 2+ Goals | M1: Concede 4+ Goals | N1: 3 Saves | O1: 6 Saves | P1: Defensive Contribution - DEF | Q1: Defensive Contribution - MID | R1: F1 XP Pre | S1: F1 Bonus Probability | T1: F1 XP | U1: F1 Difficulty | V1: F1 Opponent | W1: F1 Diff | X1: F1 Venue | Y1: F1 Factor | Z1: F2 Difficulty | AA1: F2 Opponent | AB1: F2 Diff | AC1: F2 Venue | AD1: F2 XP Pre | AE1: F2 Bonus Probability | AF1: F2 XP | AG1: F3 Difficulty | AH1: F3 Opponent | AI1: F3 Diff | AJ1: F3 Venue | AK1: F3 XP Pre | AL1: F3 Bonus Probability | AM1: F3 XP | AN1: F4 Difficulty | AO1: F4 Opponent | AP1: F4 Diff | AQ1: F4 Venue | AR1: F4 XP Pre | AS1: F4 Bonus Probability | AT1: F4 XP | AU1: F5 Difficulty | AV1: F5 Opponent | AW1: F5 Diff | AX1: F5 Venue | AY1: F5 XP Pre | AZ1: F5 Bonus Probability | BA1: F5 XP | BB1: Total XP
A2: ='Players Full'!CU2 -> David Raya | B2: =VLOOKUP(_xlfn.CONCAT('Players Full'!AK2,'Players Full'!BV2),'Players Summarised'!$A$1:$T$1000,20,0) -> GK | C2: =VLOOKUP('Players Full'!CF2,Teams!$A$1:$G$21,6,0) -> Arsenal | D2: ='Players Full'!BD2/10 -> 5.5 | E2: =IFERROR(VLOOKUP($A2,'Starting Lineups'!$A$2:$C$510,3,FALSE),0) -> 1 | F2: =VLOOKUP(A2,'Score & Assist'!$A$1:$G$2000,6,0) -> #N/A | G2: =IF(F2<0.3, 0.01,IF(F2=0.3,0.03,IF(F2<0.5,0.05,IF(F2<0.55,0.06,IF(F2<0.57,0.1,IF(F2<0.58,0.11,IF(F2<0.59,0.12,IF(F2<0.6,0.15,0.28)))))))) -> #N/A | H2: =IF(F2<0.3,0,IF(F2<0.55,0.01,IF(F2<0.59,0.02,IF(F2<0.6,0.03,0.11)))) -> #N/A | I2: =VLOOKUP(A2,'Score & Assist'!$A$1:$G$2000,7,0) -> #N/A | J2: =VLOOKUP(A2,'Yellow Card'!$C$1:$E$987,3,0) -> 0.13605442 | K2: =VLOOKUP(C2,'Team Clean Sheet'!$C$2:$F$21,4,0) -> 0.5 | L2: =VLOOKUP(C2,'Team Total Goals'!$D$2:$N$21,10,0) -> 0.17168675 | M2: =VLOOKUP(C2,'Team Total Goals'!$D$2:$N$21,11,0) -> 0.01926849 | N2: =VLOOKUP(A2,'Goalkeeper Saves'!$D$2:$N$15,10,0) -> 0.27210884 | O2: =VLOOKUP(A2,'Goalkeeper Saves'!$D$2:$N$15,11,0) -> 0 | P2: =IF(B2="DEF",IFERROR(VLOOKUP(A2,'Defensive Contribution - DEF'!A2:H498,8,FALSE),'Defensive Contribution - DEF'!K$2),0) -> 0 | Q2: =IF(B2="MID",IFERROR(VLOOKUP(A2,'Defensive Contribution - MID'!A$2:I$500,9,FALSE),'Defensive Contribution - MID'!L$2),0) -> 0 | R2: =IFERROR(IFERROR(E2,0)*IF(B2="GK",2+IFERROR(F2*10,0)+IFERROR(G2*10,0)+IFERROR(H2*10,0)+IFERROR(I2*3,0)-IFERROR(J2*1,0)+IFERROR(K2*4,0)+IFERROR(N2*1,0)+IFERROR(O2*1,0)-IFERROR(L2*2,0)-IFERROR(M2*2,0),IF(B2="DEF",2+IFERROR(F2*6,0)+IFERROR(G2*6,0)+IFERROR(H2*6,0)+IFERROR(I2*3,0)-IFERROR(J2*1,0)+IFERROR(K2*4,0)-IFERROR(L2*2,0)-IFERROR(M2*2,0)+IFERROR(P2*2,0),IF(B2="MID",2+IFERROR(F2*5,0)+IFERROR(G2*5,0)+IFERROR(H2*5,0)+IFERROR(I2*3,0)-IFERROR(J2*1,0)+IFERROR(K2*1,0)+IFERROR(Q2*2,0),IF(B2="FWD",2+IFERROR(F2*4,0)+IFERROR(G2*4,0)+IFERROR(H2*4,0)+IFERROR(I2*3,0)-IFERROR(J2*1,0),"ERROR")))),0) -> 3.7541439 | S2: =MAX(0, MIN(1, -0.021039 + 0.023522 * R2)) -> 0.067265974 | T2: =R2+S2*2 -> 3.8886759 | U2: =VLOOKUP($C2,'Team Fixtures'!$A$2:$Q$21,2,FALSE) -> 0.88924459 | V2: =VLOOKUP($C2,'Team Fixtures'!$A$2:$Q$21,4,FALSE) -> 0.028011204 | W2: =VLOOKUP($C2,'Team Fixtures'!$A$2:$Q$21,5,FALSE) -> 0.86123338 | X2: =VLOOKUP($C2,'Team Fixtures'!$A$2:$Q$21,6,FALSE) -> H | Y2: =R2/(2.926+0.578*U2-0.576*V2-0.561*W2+0.469*IF(X2="H",1,0)) -> 1.1010198 | Z2: =VLOOKUP($C2,'Team Fixtures'!$A$2:$Q$21,2,FALSE) -> 0.88924459 | AA2: =VLOOKUP($C2,'Team Fixtures'!$A$2:$Q$21,8,FALSE) -> 0.89678056 | AB2: =VLOOKUP($C2,'Team Fixtures'!$A$2:$Q$21,9,FALSE) -> -0.0075359711 | AC2: =VLOOKUP($C2,'Team Fixtures'!$A$2:$Q$21,10,FALSE) -> A | AD2: =IFERROR((2.926+0.578*Z2-0.576*AA2-0.561*AB2+0.469*IF(AC2="H",1,0))*$Y2,0) -> 3.2234177 | AE2: =MAX(0, MIN(1, -0.021039 + 0.023522 * AD2)) -> 0.05478223 | AF2: =AD2+AE2*2 -> 3.3329821 | AG2: =VLOOKUP($C2,'Team Fixtures'!$A$2:$Q$21,2,FALSE) -> 0.88924459 | AH2: =VLOOKUP($C2,'Team Fixtures'!$A$2:$Q$21,12,FALSE) -> 0.10582011 | AI2: =VLOOKUP($C2,'Team Fixtures'!$A$2:$Q$21,13,FALSE) -> 0.78342448 | AJ2: =VLOOKUP($C2,'Team Fixtures'!$A$2:$Q$21,14,FALSE) -> H | AK2: =IFERROR((2.926+0.578*AG2-0.576*AH2-0.561*AI2+0.469*IF(AJ2="H",1,0))*$Y2,0) -> 3.7528589 | AL2: =MAX(0, MIN(1, -0.021039 + 0.023522 * AK2)) -> 0.067235747 | AM2: =AK2+AL2*2 -> 3.8873304 | AN2: =VLOOKUP($C2,'Team Fixtures'!$A$2:$Q$21,2,FALSE) -> 0.88924459 | AO2: =VLOOKUP($C2,'Team Fixtures'!$A$2:$Q$21,16,FALSE) -> 0.87939146 | AP2: =VLOOKUP($C2,'Team Fixtures'!$A$2:$Q$21,17,FALSE) -> 0.0098531256 | AQ2: =VLOOKUP($C2,'Team Fixtures'!$A$2:$V$21,18,FALSE) -> H | AR2: =IFERROR((2.926+0.578*AN2-0.576*AO2-0.561*AP2+0.469*IF(AQ2="H",1,0))*$Y2,0) -> 3.7400832 | AS2: =MAX(0, MIN(1, -0.021039 + 0.023522 * AR2)) -> 0.066935236 | AT2: =AR2+AS2*2 -> 3.8739536 | AU2: =VLOOKUP($C2,'Team Fixtures'!$A$2:$Q$21,2,FALSE) -> 0.88924459 | AV2: =VLOOKUP($C2,'Team Fixtures'!$A$2:$V$21,20,FALSE) -> 0.50125313 | AW2: =VLOOKUP($C2,'Team Fixtures'!$A$2:$V$21,21,FALSE) -> 0.38799145 | AX2: =VLOOKUP($C2,'Team Fixtures'!$A$2:$V$21,22,FALSE) -> A | AY2: =IFERROR((2.926+0.578*AU2-0.576*AV2-0.561*AW2+0.469*IF(AX2="H",1,0))*$Y2,0) -> 3.2299499 | AZ2: =MAX(0, MIN(1, -0.021039 + 0.023522 * AY2)) -> 0.054935882 | BA2: =AY2+AZ2*2 -> 3.3398217 | BB2: =IFERROR(T2*1+AF2*0.85+AM2*0.7+AT2*0.55+BA2*0.4,0) -> 12.909445
A3: ='Players Full'!CU3 -> Kepa Arrizabalaga | B3: =VLOOKUP(_xlfn.CONCAT('Players Full'!AK3,'Players Full'!BV3),'Players Summarised'!$A$1:$T$1000,20,0) -> GK | C3: =VLOOKUP('Players Full'!CF3,Teams!$A$1:$G$21,6,0) -> Arsenal | D3: ='Players Full'!BD3/10 -> 4.5 | E3: =IFERROR(VLOOKUP($A3,'Starting Lineups'!$A$2:$C$510,3,FALSE),0) -> 0 | F3: =VLOOKUP(A3,'Score & Assist'!$A$1:$G$2000,6,0) -> #N/A | G3: =IF(F3<0.3, 0.01,IF(F3=0.3,0.03,IF(F3<0.5,0.05,IF(F3<0.55,0.06,IF(F3<0.57,0.1,IF(F3<0.58,0.11,IF(F3<0.59,0.12,IF(F3<0.6,0.15,0.28)))))))) -> #N/A | H3: =IF(F3<0.3,0,IF(F3<0.55,0.01,IF(F3<0.59,0.02,IF(F3<0.6,0.03,0.11)))) -> #N/A | I3: =VLOOKUP(A3,'Score & Assist'!$A$1:$G$2000,7,0) -> #N/A | J3: =VLOOKUP(A3,'Yellow Card'!$C$1:$E$987,3,0) -> 0.13605442 | K3: =VLOOKUP(C3,'Team Clean Sheet'!$C$2:$F$21,4,0) -> 0.5 | L3: =VLOOKUP(C3,'Team Total Goals'!$D$2:$N$21,10,0) -> 0.17168675 | M3: =VLOOKUP(C3,'Team Total Goals'!$D$2:$N$21,11,0) -> 0.01926849 | N3: =VLOOKUP(A3,'Goalkeeper Saves'!$D$2:$N$15,10,0) -> #N/A | O3: =VLOOKUP(A3,'Goalkeeper Saves'!$D$2:$N$15,11,0) -> #N/A | P3: =IF(B3="DEF",IFERROR(VLOOKUP(A3,'Defensive Contribution - DEF'!A3:H499,8,FALSE),'Defensive Contribution - DEF'!K$2),0) -> 0 | Q3: =IF(B3="MID",IFERROR(VLOOKUP(A3,'Defensive Contribution - MID'!A$2:I$500,9,FALSE),'Defensive Contribution - MID'!L$2),0) -> 0 | R3: =IFERROR(IFERROR(E3,0)*IF(B3="GK",2+IFERROR(F3*10,0)+IFERROR(G3*10,0)+IFERROR(H3*10,0)+IFERROR(I3*3,0)-IFERROR(J3*1,0)+IFERROR(K3*4,0)+IFERROR(N3*1,0)+IFERROR(O3*1,0)-IFERROR(L3*2,0)-IFERROR(M3*2,0),IF(B3="DEF",2+IFERROR(F3*6,0)+IFERROR(G3*6,0)+IFERROR(H3*6,0)+IFERROR(I3*3,0)-IFERROR(J3*1,0)+IFERROR(K3*4,0)-IFERROR(L3*2,0)-IFERROR(M3*2,0)+IFERROR(P3*2,0),IF(B3="MID",2+IFERROR(F3*5,0)+IFERROR(G3*5,0)+IFERROR(H3*5,0)+IFERROR(I3*3,0)-IFERROR(J3*1,0)+IFERROR(K3*1,0)+IFERROR(Q3*2,0),IF(B3="FWD",2+IFERROR(F3*4,0)+IFERROR(G3*4,0)+IFERROR(H3*4,0)+IFERROR(I3*3,0)-IFERROR(J3*1,0),"ERROR")))),0) -> 0 | S3: =MAX(0, MIN(1, -0.021039 + 0.023522 * R3)) -> 0 | T3: =R3+S3*2 -> 0 | U3: =VLOOKUP($C3,'Team Fixtures'!$A$2:$Q$21,2,FALSE) -> 0.88924459 | V3: =VLOOKUP($C3,'Team Fixtures'!$A$2:$Q$21,4,FALSE) -> 0.028011204 | W3: =VLOOKUP($C3,'Team Fixtures'!$A$2:$Q$21,5,FALSE) -> 0.86123338 | X3: =VLOOKUP($C3,'Team Fixtures'!$A$2:$Q$21,6,FALSE) -> H | Y3: =R3/(2.926+0.578*U3-0.576*V3-0.561*W3+0.469*IF(X3="H",1,0)) -> 0 | Z3: =VLOOKUP($C3,'Team Fixtures'!$A$2:$Q$21,2,FALSE) -> 0.88924459 | AA3: =VLOOKUP($C3,'Team Fixtures'!$A$2:$Q$21,8,FALSE) -> 0.89678056 | AB3: =VLOOKUP($C3,'Team Fixtures'!$A$2:$Q$21,9,FALSE) -> -0.0075359711 | AC3: =VLOOKUP($C3,'Team Fixtures'!$A$2:$Q$21,10,FALSE) -> A | AD3: =IFERROR((2.926+0.578*Z3-0.576*AA3-0.561*AB3+0.469*IF(AC3="H",1,0))*$Y3,0) -> 0 | AE3: =MAX(0, MIN(1, -0.021039 + 0.023522 * AD3)) -> 0 | AF3: =AD3+AE3*2 -> 0 | AG3: =VLOOKUP($C3,'Team Fixtures'!$A$2:$Q$21,2,FALSE) -> 0.88924459 | AH3: =VLOOKUP($C3,'Team Fixtures'!$A$2:$Q$21,12,FALSE) -> 0.10582011 | AI3: =VLOOKUP($C3,'Team Fixtures'!$A$2:$Q$21,13,FALSE) -> 0.78342448 | AJ3: =VLOOKUP($C3,'Team Fixtures'!$A$2:$Q$21,14,FALSE) -> H | AK3: =IFERROR((2.926+0.578*AG3-0.576*AH3-0.561*AI3+0.469*IF(AJ3="H",1,0))*$Y3,0) -> 0 | AL3: =MAX(0, MIN(1, -0.021039 + 0.023522 * AK3)) -> 0 | AM3: =AK3+AL3*2 -> 0 | AN3: =VLOOKUP($C3,'Team Fixtures'!$A$2:$Q$21,2,FALSE) -> 0.88924459 | AO3: =VLOOKUP($C3,'Team Fixtures'!$A$2:$Q$21,16,FALSE) -> 0.87939146 | AP3: =VLOOKUP($C3,'Team Fixtures'!$A$2:$Q$21,17,FALSE) -> 0.0098531256 | AQ3: =VLOOKUP($C3,'Team Fixtures'!$A$2:$V$21,18,FALSE) -> H | AR3: =IFERROR((2.926+0.578*AN3-0.576*AO3-0.561*AP3+0.469*IF(AQ3="H",1,0))*$Y3,0) -> 0 | AS3: =MAX(0, MIN(1, -0.021039 + 0.023522 * AR3)) -> 0 | AT3: =AR3+AS3*2 -> 0 | AU3: =VLOOKUP($C3,'Team Fixtures'!$A$2:$Q$21,2,FALSE) -> 0.88924459 | AV3: =VLOOKUP($C3,'Team Fixtures'!$A$2:$V$21,20,FALSE) -> 0.50125313 | AW3: =VLOOKUP($C3,'Team Fixtures'!$A$2:$V$21,21,FALSE) -> 0.38799145 | AX3: =VLOOKUP($C3,'Team Fixtures'!$A$2:$V$21,22,FALSE) -> A | AY3: =IFERROR((2.926+0.578*AU3-0.576*AV3-0.561*AW3+0.469*IF(AX3="H",1,0))*$Y3,0) -> 0 | AZ3: =MAX(0, MIN(1, -0.021039 + 0.023522 * AY3)) -> 0 | BA3: =AY3+AZ3*2 -> 0 | BB3: =IFERROR(T3*1+AF3*0.85+AM3*0.7+AT3*0.55+BA3*0.4,0) -> 0
A4: ='Players Full'!CU4 -> Karl Hein | B4: =VLOOKUP(_xlfn.CONCAT('Players Full'!AK4,'Players Full'!BV4),'Players Summarised'!$A$1:$T$1000,20,0) -> GK | C4: =VLOOKUP('Players Full'!CF4,Teams!$A$1:$G$21,6,0) -> Arsenal | D4: ='Players Full'!BD4/10 -> 4 | E4: =IFERROR(VLOOKUP($A4,'Starting Lineups'!$A$2:$C$510,3,FALSE),0) -> 0 | F4: =VLOOKUP(A4,'Score & Assist'!$A$1:$G$2000,6,0) -> #N/A | G4: =IF(F4<0.3, 0.01,IF(F4=0.3,0.03,IF(F4<0.5,0.05,IF(F4<0.55,0.06,IF(F4<0.57,0.1,IF(F4<0.58,0.11,IF(F4<0.59,0.12,IF(F4<0.6,0.15,0.28)))))))) -> #N/A | H4: =IF(F4<0.3,0,IF(F4<0.55,0.01,IF(F4<0.59,0.02,IF(F4<0.6,0.03,0.11)))) -> #N/A | I4: =VLOOKUP(A4,'Score & Assist'!$A$1:$G$2000,7,0) -> #N/A | J4: =VLOOKUP(A4,'Yellow Card'!$C$1:$E$987,3,0) -> #N/A | K4: =VLOOKUP(C4,'Team Clean Sheet'!$C$2:$F$21,4,0) -> 0.5 | L4: =VLOOKUP(C4,'Team Total Goals'!$D$2:$N$21,10,0) -> 0.17168675 | M4: =VLOOKUP(C4,'Team Total Goals'!$D$2:$N$21,11,0) -> 0.01926849 | N4: =VLOOKUP(A4,'Goalkeeper Saves'!$D$2:$N$15,10,0) -> #N/A | O4: =VLOOKUP(A4,'Goalkeeper Saves'!$D$2:$N$15,11,0) -> #N/A | P4: =IF(B4="DEF",IFERROR(VLOOKUP(A4,'Defensive Contribution - DEF'!A4:H500,8,FALSE),'Defensive Contribution - DEF'!K$2),0) -> 0 | Q4: =IF(B4="MID",IFERROR(VLOOKUP(A4,'Defensive Contribution - MID'!A$2:I$500,9,FALSE),'Defensive Contribution - MID'!L$2),0) -> 0 | R4: =IFERROR(IFERROR(E4,0)*IF(B4="GK",2+IFERROR(F4*10,0)+IFERROR(G4*10,0)+IFERROR(H4*10,0)+IFERROR(I4*3,0)-IFERROR(J4*1,0)+IFERROR(K4*4,0)+IFERROR(N4*1,0)+IFERROR(O4*1,0)-IFERROR(L4*2,0)-IFERROR(M4*2,0),IF(B4="DEF",2+IFERROR(F4*6,0)+IFERROR(G4*6,0)+IFERROR(H4*6,0)+IFERROR(I4*3,0)-IFERROR(J4*1,0)+IFERROR(K4*4,0)-IFERROR(L4*2,0)-IFERROR(M4*2,0)+IFERROR(P4*2,0),IF(B4="MID",2+IFERROR(F4*5,0)+IFERROR(G4*5,0)+IFERROR(H4*5,0)+IFERROR(I4*3,0)-IFERROR(J4*1,0)+IFERROR(K4*1,0)+IFERROR(Q4*2,0),IF(B4="FWD",2+IFERROR(F4*4,0)+IFERROR(G4*4,0)+IFERROR(H4*4,0)+IFERROR(I4*3,0)-IFERROR(J4*1,0),"ERROR")))),0) -> 0 | S4: =MAX(0, MIN(1, -0.021039 + 0.023522 * R4)) -> 0 | T4: =R4+S4*2 -> 0 | U4: =VLOOKUP($C4,'Team Fixtures'!$A$2:$Q$21,2,FALSE) -> 0.88924459 | V4: =VLOOKUP($C4,'Team Fixtures'!$A$2:$Q$21,4,FALSE) -> 0.028011204 | W4: =VLOOKUP($C4,'Team Fixtures'!$A$2:$Q$21,5,FALSE) -> 0.86123338 | X4: =VLOOKUP($C4,'Team Fixtures'!$A$2:$Q$21,6,FALSE) -> H | Y4: =R4/(2.926+0.578*U4-0.576*V4-0.561*W4+0.469*IF(X4="H",1,0)) -> 0 | Z4: =VLOOKUP($C4,'Team Fixtures'!$A$2:$Q$21,2,FALSE) -> 0.88924459 | AA4: =VLOOKUP($C4,'Team Fixtures'!$A$2:$Q$21,8,FALSE) -> 0.89678056 | AB4: =VLOOKUP($C4,'Team Fixtures'!$A$2:$Q$21,9,FALSE) -> -0.0075359711 | AC4: =VLOOKUP($C4,'Team Fixtures'!$A$2:$Q$21,10,FALSE) -> A | AD4: =IFERROR((2.926+0.578*Z4-0.576*AA4-0.561*AB4+0.469*IF(AC4="H",1,0))*$Y4,0) -> 0 | AE4: =MAX(0, MIN(1, -0.021039 + 0.023522 * AD4)) -> 0 | AF4: =AD4+AE4*2 -> 0 | AG4: =VLOOKUP($C4,'Team Fixtures'!$A$2:$Q$21,2,FALSE) -> 0.88924459 | AH4: =VLOOKUP($C4,'Team Fixtures'!$A$2:$Q$21,12,FALSE) -> 0.10582011 | AI4: =VLOOKUP($C4,'Team Fixtures'!$A$2:$Q$21,13,FALSE) -> 0.78342448 | AJ4: =VLOOKUP($C4,'Team Fixtures'!$A$2:$Q$21,14,FALSE) -> H | AK4: =IFERROR((2.926+0.578*AG4-0.576*AH4-0.561*AI4+0.469*IF(AJ4="H",1,0))*$Y4,0) -> 0 | AL4: =MAX(0, MIN(1, -0.021039 + 0.023522 * AK4)) -> 0 | AM4: =AK4+AL4*2 -> 0 | AN4: =VLOOKUP($C4,'Team Fixtures'!$A$2:$Q$21,2,FALSE) -> 0.88924459 | AO4: =VLOOKUP($C4,'Team Fixtures'!$A$2:$Q$21,16,FALSE) -> 0.87939146 | AP4: =VLOOKUP($C4,'Team Fixtures'!$A$2:$Q$21,17,FALSE) -> 0.0098531256 | AQ4: =VLOOKUP($C4,'Team Fixtures'!$A$2:$V$21,18,FALSE) -> H | AR4: =IFERROR((2.926+0.578*AN4-0.576*AO4-0.561*AP4+0.469*IF(AQ4="H",1,0))*$Y4,0) -> 0 | AS4: =MAX(0, MIN(1, -0.021039 + 0.023522 * AR4)) -> 0 | AT4: =AR4+AS4*2 -> 0 | AU4: =VLOOKUP($C4,'Team Fixtures'!$A$2:$Q$21,2,FALSE) -> 0.88924459 | AV4: =VLOOKUP($C4,'Team Fixtures'!$A$2:$V$21,20,FALSE) -> 0.50125313 | AW4: =VLOOKUP($C4,'Team Fixtures'!$A$2:$V$21,21,FALSE) -> 0.38799145 | AX4: =VLOOKUP($C4,'Team Fixtures'!$A$2:$V$21,22,FALSE) -> A | AY4: =IFERROR((2.926+0.578*AU4-0.576*AV4-0.561*AW4+0.469*IF(AX4="H",1,0))*$Y4,0) -> 0 | AZ4: =MAX(0, MIN(1, -0.021039 + 0.023522 * AY4)) -> 0 | BA4: =AY4+AZ4*2 -> 0 | BB4: =IFERROR(T4*1+AF4*0.85+AM4*0.7+AT4*0.55+BA4*0.4,0) -> 0
A5: ='Players Full'!CU5 -> Tommy Setford | B5: =VLOOKUP(_xlfn.CONCAT('Players Full'!AK5,'Players Full'!BV5),'Players Summarised'!$A$1:$T$1000,20,0) -> GK | C5: =VLOOKUP('Players Full'!CF5,Teams!$A$1:$G$21,6,0) -> Arsenal | D5: ='Players Full'!BD5/10 -> 4 | E5: =IFERROR(VLOOKUP($A5,'Starting Lineups'!$A$2:$C$510,3,FALSE),0) -> 0 | F5: =VLOOKUP(A5,'Score & Assist'!$A$1:$G$2000,6,0) -> #N/A | G5: =IF(F5<0.3, 0.01,IF(F5=0.3,0.03,IF(F5<0.5,0.05,IF(F5<0.55,0.06,IF(F5<0.57,0.1,IF(F5<0.58,0.11,IF(F5<0.59,0.12,IF(F5<0.6,0.15,0.28)))))))) -> #N/A | H5: =IF(F5<0.3,0,IF(F5<0.55,0.01,IF(F5<0.59,0.02,IF(F5<0.6,0.03,0.11)))) -> #N/A | I5: =VLOOKUP(A5,'Score & Assist'!$A$1:$G$2000,7,0) -> #N/A | J5: =VLOOKUP(A5,'Yellow Card'!$C$1:$E$987,3,0) -> 0.13605442 | K5: =VLOOKUP(C5,'Team Clean Sheet'!$C$2:$F$21,4,0) -> 0.5 | L5: =VLOOKUP(C5,'Team Total Goals'!$D$2:$N$21,10,0) -> 0.17168675 | M5: =VLOOKUP(C5,'Team Total Goals'!$D$2:$N$21,11,0) -> 0.01926849 | N5: =VLOOKUP(A5,'Goalkeeper Saves'!$D$2:$N$15,10,0) -> #N/A | O5: =VLOOKUP(A5,'Goalkeeper Saves'!$D$2:$N$15,11,0) -> #N/A | P5: =IF(B5="DEF",IFERROR(VLOOKUP(A5,'Defensive Contribution - DEF'!A5:H501,8,FALSE),'Defensive Contribution - DEF'!K$2),0) -> 0 | Q5: =IF(B5="MID",IFERROR(VLOOKUP(A5,'Defensive Contribution - MID'!A$2:I$500,9,FALSE),'Defensive Contribution - MID'!L$2),0) -> 0 | R5: =IFERROR(IFERROR(E5,0)*IF(B5="GK",2+IFERROR(F5*10,0)+IFERROR(G5*10,0)+IFERROR(H5*10,0)+IFERROR(I5*3,0)-IFERROR(J5*1,0)+IFERROR(K5*4,0)+IFERROR(N5*1,0)+IFERROR(O5*1,0)-IFERROR(L5*2,0)-IFERROR(M5*2,0),IF(B5="DEF",2+IFERROR(F5*6,0)+IFERROR(G5*6,0)+IFERROR(H5*6,0)+IFERROR(I5*3,0)-IFERROR(J5*1,0)+IFERROR(K5*4,0)-IFERROR(L5*2,0)-IFERROR(M5*2,0)+IFERROR(P5*2,0),IF(B5="MID",2+IFERROR(F5*5,0)+IFERROR(G5*5,0)+IFERROR(H5*5,0)+IFERROR(I5*3,0)-IFERROR(J5*1,0)+IFERROR(K5*1,0)+IFERROR(Q5*2,0),IF(B5="FWD",2+IFERROR(F5*4,0)+IFERROR(G5*4,0)+IFERROR(H5*4,0)+IFERROR(I5*3,0)-IFERROR(J5*1,0),"ERROR")))),0) -> 0 | S5: =MAX(0, MIN(1, -0.021039 + 0.023522 * R5)) -> 0 | T5: =R5+S5*2 -> 0 | U5: =VLOOKUP($C5,'Team Fixtures'!$A$2:$Q$21,2,FALSE) -> 0.88924459 | V5: =VLOOKUP($C5,'Team Fixtures'!$A$2:$Q$21,4,FALSE) -> 0.028011204 | W5: =VLOOKUP($C5,'Team Fixtures'!$A$2:$Q$21,5,FALSE) -> 0.86123338 | X5: =VLOOKUP($C5,'Team Fixtures'!$A$2:$Q$21,6,FALSE) -> H | Y5: =R5/(2.926+0.578*U5-0.576*V5-0.561*W5+0.469*IF(X5="H",1,0)) -> 0 | Z5: =VLOOKUP($C5,'Team Fixtures'!$A$2:$Q$21,2,FALSE) -> 0.88924459 | AA5: =VLOOKUP($C5,'Team Fixtures'!$A$2:$Q$21,8,FALSE) -> 0.89678056 | AB5: =VLOOKUP($C5,'Team Fixtures'!$A$2:$Q$21,9,FALSE) -> -0.0075359711 | AC5: =VLOOKUP($C5,'Team Fixtures'!$A$2:$Q$21,10,FALSE) -> A | AD5: =IFERROR((2.926+0.578*Z5-0.576*AA5-0.561*AB5+0.469*IF(AC5="H",1,0))*$Y5,0) -> 0 | AE5: =MAX(0, MIN(1, -0.021039 + 0.023522 * AD5)) -> 0 | AF5: =AD5+AE5*2 -> 0 | AG5: =VLOOKUP($C5,'Team Fixtures'!$A$2:$Q$21,2,FALSE) -> 0.88924459 | AH5: =VLOOKUP($C5,'Team Fixtures'!$A$2:$Q$21,12,FALSE) -> 0.10582011 | AI5: =VLOOKUP($C5,'Team Fixtures'!$A$2:$Q$21,13,FALSE) -> 0.78342448 | AJ5: =VLOOKUP($C5,'Team Fixtures'!$A$2:$Q$21,14,FALSE) -> H | AK5: =IFERROR((2.926+0.578*AG5-0.576*AH5-0.561*AI5+0.469*IF(AJ5="H",1,0))*$Y5,0) -> 0 | AL5: =MAX(0, MIN(1, -0.021039 + 0.023522 * AK5)) -> 0 | AM5: =AK5+AL5*2 -> 0 | AN5: =VLOOKUP($C5,'Team Fixtures'!$A$2:$Q$21,2,FALSE) -> 0.88924459 | AO5: =VLOOKUP($C5,'Team Fixtures'!$A$2:$Q$21,16,FALSE) -> 0.87939146 | AP5: =VLOOKUP($C5,'Team Fixtures'!$A$2:$Q$21,17,FALSE) -> 0.0098531256 | AQ5: =VLOOKUP($C5,'Team Fixtures'!$A$2:$V$21,18,FALSE) -> H | AR5: =IFERROR((2.926+0.578*AN5-0.576*AO5-0.561*AP5+0.469*IF(AQ5="H",1,0))*$Y5,0) -> 0 | AS5: =MAX(0, MIN(1, -0.021039 + 0.023522 * AR5)) -> 0 | AT5: =AR5+AS5*2 -> 0 | AU5: =VLOOKUP($C5,'Team Fixtures'!$A$2:$Q$21,2,FALSE) -> 0.88924459 | AV5: =VLOOKUP($C5,'Team Fixtures'!$A$2:$V$21,20,FALSE) -> 0.50125313 | AW5: =VLOOKUP($C5,'Team Fixtures'!$A$2:$V$21,21,FALSE) -> 0.38799145 | AX5: =VLOOKUP($C5,'Team Fixtures'!$A$2:$V$21,22,FALSE) -> A | AY5: =IFERROR((2.926+0.578*AU5-0.576*AV5-0.561*AW5+0.469*IF(AX5="H",1,0))*$Y5,0) -> 0 | AZ5: =MAX(0, MIN(1, -0.021039 + 0.023522 * AY5)) -> 0 | BA5: =AY5+AZ5*2 -> 0 | BB5: =IFERROR(T5*1+AF5*0.85+AM5*0.7+AT5*0.55+BA5*0.4,0) -> 0
A6: ='Players Full'!CU6 -> Gabriel Magalhaes | B6: =VLOOKUP(_xlfn.CONCAT('Players Full'!AK6,'Players Full'!BV6),'Players Summarised'!$A$1:$T$1000,20,0) -> DEF | C6: =VLOOKUP('Players Full'!CF6,Teams!$A$1:$G$21,6,0) -> Arsenal | D6: ='Players Full'!BD6/10 -> 6 | E6: =IFERROR(VLOOKUP($A6,'Starting Lineups'!$A$2:$C$510,3,FALSE),0) -> 1 | F6: =VLOOKUP(A6,'Score & Assist'!$A$1:$G$2000,6,0) -> 0.19047619 | G6: =IF(F6<0.3, 0.01,IF(F6=0.3,0.03,IF(F6<0.5,0.05,IF(F6<0.55,0.06,IF(F6<0.57,0.1,IF(F6<0.58,0.11,IF(F6<0.59,0.12,IF(F6<0.6,0.15,0.28)))))))) -> 0.01 | H6: =IF(F6<0.3,0,IF(F6<0.55,0.01,IF(F6<0.59,0.02,IF(F6<0.6,0.03,0.11)))) -> 0 | I6: =VLOOKUP(A6,'Score & Assist'!$A$1:$G$2000,7,0) -> 0.050125313 | J6: =VLOOKUP(A6,'Yellow Card'!$C$1:$E$987,3,0) -> 0.13605442 | K6: =VLOOKUP(C6,'Team Clean Sheet'!$C$2:$F$21,4,0) -> 0.5 | L6: =VLOOKUP(C6,'Team Total Goals'!$D$2:$N$21,10,0) -> 0.17168675 | M6: =VLOOKUP(C6,'Team Total Goals'!$D$2:$N$21,11,0) -> 0.01926849 | N6: =VLOOKUP(A6,'Goalkeeper Saves'!$D$2:$N$15,10,0) -> #N/A | O6: =VLOOKUP(A6,'Goalkeeper Saves'!$D$2:$N$15,11,0) -> #N/A | P6: =IF(B6="DEF",IFERROR(VLOOKUP(A6,'Defensive Contribution - DEF'!A6:H502,8,FALSE),'Defensive Contribution - DEF'!K$2),0) -> 0.11320273 | Q6: =IF(B6="MID",IFERROR(VLOOKUP(A6,'Defensive Contribution - MID'!A$2:I$500,9,FALSE),'Defensive Contribution - MID'!L$2),0) -> 0 | R6: =IFERROR(IFERROR(E6,0)*IF(B6="GK",2+IFERROR(F6*10,0)+IFERROR(G6*10,0)+IFERROR(H6*10,0)+IFERROR(I6*3,0)-IFERROR(J6*1,0)+IFERROR(K6*4,0)+IFERROR(N6*1,0)+IFERROR(O6*1,0)-IFERROR(L6*2,0)-IFERROR(M6*2,0),IF(B6="DEF",2+IFERROR(F6*6,0)+IFERROR(G6*6,0)+IFERROR(H6*6,0)+IFERROR(I6*3,0)-IFERROR(J6*1,0)+IFERROR(K6*4,0)-IFERROR(L6*2,0)-IFERROR(M6*2,0)+IFERROR(P6*2,0),IF(B6="MID",2+IFERROR(F6*5,0)+IFERROR(G6*5,0)+IFERROR(H6*5,0)+IFERROR(I6*3,0)-IFERROR(J6*1,0)+IFERROR(K6*1,0)+IFERROR(Q6*2,0),IF(B6="FWD",2+IFERROR(F6*4,0)+IFERROR(G6*4,0)+IFERROR(H6*4,0)+IFERROR(I6*3,0)-IFERROR(J6*1,0),"ERROR")))),0) -> 5.0616736 | S6: =MAX(0, MIN(1, -0.021039 + 0.023522 * R6)) -> 0.098021688 | T6: =R6+S6*2 -> 5.257717 | U6: =VLOOKUP($C6,'Team Fixtures'!$A$2:$Q$21,2,FALSE) -> 0.88924459 | V6: =VLOOKUP($C6,'Team Fixtures'!$A$2:$Q$21,4,FALSE) -> 0.028011204 | W6: =VLOOKUP($C6,'Team Fixtures'!$A$2:$Q$21,5,FALSE) -> 0.86123338 | X6: =VLOOKUP($C6,'Team Fixtures'!$A$2:$Q$21,6,FALSE) -> H | Y6: =R6/(2.926+0.578*U6-0.576*V6-0.561*W6+0.469*IF(X6="H",1,0)) -> 1.4844937 | Z6: =VLOOKUP($C6,'Team Fixtures'!$A$2:$Q$21,2,FALSE) -> 0.88924459 | AA6: =VLOOKUP($C6,'Team Fixtures'!$A$2:$Q$21,8,FALSE) -> 0.89678056 | AB6: =VLOOKUP($C6,'Team Fixtures'!$A$2:$Q$21,9,FALSE) -> -0.0075359711 | AC6: =VLOOKUP($C6,'Team Fixtures'!$A$2:$Q$21,10,FALSE) -> A | AD6: =IFERROR((2.926+0.578*Z6-0.576*AA6-0.561*AB6+0.469*IF(AC6="H",1,0))*$Y6,0) -> 4.3461009 | AE6: =MAX(0, MIN(1, -0.021039 + 0.023522 * AD6)) -> 0.081189985 | AF6: =AD6+AE6*2 -> 4.5084808 | AG6: =VLOOKUP($C6,'Team Fixtures'!$A$2:$Q$21,2,FALSE) -> 0.88924459 | AH6: =VLOOKUP($C6,'Team Fixtures'!$A$2:$Q$21,12,FALSE) -> 0.10582011 | AI6: =VLOOKUP($C6,'Team Fixtures'!$A$2:$Q$21,13,FALSE) -> 0.78342448 | AJ6: =VLOOKUP($C6,'Team Fixtures'!$A$2:$Q$21,14,FALSE) -> H | AK6: =IFERROR((2.926+0.578*AG6-0.576*AH6-0.561*AI6+0.469*IF(AJ6="H",1,0))*$Y6,0) -> 5.059941 | AL6: =MAX(0, MIN(1, -0.021039 + 0.023522 * AK6)) -> 0.097980933 | AM6: =AK6+AL6*2 -> 5.2559029 | AN6: =VLOOKUP($C6,'Team Fixtures'!$A$2:$Q$21,2,FALSE) -> 0.88924459 | AO6: =VLOOKUP($C6,'Team Fixtures'!$A$2:$Q$21,16,FALSE) -> 0.87939146 | AP6: =VLOOKUP($C6,'Team Fixtures'!$A$2:$Q$21,17,FALSE) -> 0.0098531256 | AQ6: =VLOOKUP($C6,'Team Fixtures'!$A$2:$V$21,18,FALSE) -> H | AR6: =IFERROR((2.926+0.578*AN6-0.576*AO6-0.561*AP6+0.469*IF(AQ6="H",1,0))*$Y6,0) -> 5.0427156 | AS6: =MAX(0, MIN(1, -0.021039 + 0.023522 * AR6)) -> 0.097575757 | AT6: =AR6+AS6*2 -> 5.2378671 | AU6: =VLOOKUP($C6,'Team Fixtures'!$A$2:$Q$21,2,FALSE) -> 0.88924459 | AV6: =VLOOKUP($C6,'Team Fixtures'!$A$2:$V$21,20,FALSE) -> 0.50125313 | AW6: =VLOOKUP($C6,'Team Fixtures'!$A$2:$V$21,21,FALSE) -> 0.38799145 | AX6: =VLOOKUP($C6,'Team Fixtures'!$A$2:$V$21,22,FALSE) -> A | AY6: =IFERROR((2.926+0.578*AU6-0.576*AV6-0.561*AW6+0.469*IF(AX6="H",1,0))*$Y6,0) -> 4.3549082 | AZ6: =MAX(0, MIN(1, -0.021039 + 0.023522 * AY6)) -> 0.081397152 | BA6: =AY6+AZ6*2 -> 4.5177025 | BB6: =IFERROR(T6*1+AF6*0.85+AM6*0.7+AT6*0.55+BA6*0.4,0) -> 17.456966
A7: ='Players Full'!CU7 -> William Saliba | B7: =VLOOKUP(_xlfn.CONCAT('Players Full'!AK7,'Players Full'!BV7),'Players Summarised'!$A$1:$T$1000,20,0) -> DEF | C7: =VLOOKUP('Players Full'!CF7,Teams!$A$1:$G$21,6,0) -> Arsenal | D7: ='Players Full'!BD7/10 -> 6 | E7: =IFERROR(VLOOKUP($A7,'Starting Lineups'!$A$2:$C$510,3,FALSE),0) -> 1 | F7: =VLOOKUP(A7,'Score & Assist'!$A$1:$G$2000,6,0) -> 0.10025063 | G7: =IF(F7<0.3, 0.01,IF(F7=0.3,0.03,IF(F7<0.5,0.05,IF(F7<0.55,0.06,IF(F7<0.57,0.1,IF(F7<0.58,0.11,IF(F7<0.59,0.12,IF(F7<0.6,0.15,0.28)))))))) -> 0.01 | H7: =IF(F7<0.3,0,IF(F7<0.55,0.01,IF(F7<0.59,0.02,IF(F7<0.6,0.03,0.11)))) -> 0 | I7: =VLOOKUP(A7,'Score & Assist'!$A$1:$G$2000,7,0) -> 0.045351474 | J7: =VLOOKUP(A7,'Yellow Card'!$C$1:$E$987,3,0) -> 0.11204482 | K7: =VLOOKUP(C7,'Team Clean Sheet'!$C$2:$F$21,4,0) -> 0.5 | L7: =VLOOKUP(C7,'Team Total Goals'!$D$2:$N$21,10,0) -> 0.17168675 | M7: =VLOOKUP(C7,'Team Total Goals'!$D$2:$N$21,11,0) -> 0.01926849 | N7: =VLOOKUP(A7,'Goalkeeper Saves'!$D$2:$N$15,10,0) -> #N/A | O7: =VLOOKUP(A7,'Goalkeeper Saves'!$D$2:$N$15,11,0) -> #N/A | P7: =IF(B7="DEF",IFERROR(VLOOKUP(A7,'Defensive Contribution - DEF'!A7:H503,8,FALSE),'Defensive Contribution - DEF'!K$2),0) -> 0.11489343 | Q7: =IF(B7="MID",IFERROR(VLOOKUP(A7,'Defensive Contribution - MID'!A$2:I$500,9,FALSE),'Defensive Contribution - MID'!L$2),0) -> 0 | R7: =IFERROR(IFERROR(E7,0)*IF(B7="GK",2+IFERROR(F7*10,0)+IFERROR(G7*10,0)+IFERROR(H7*10,0)+IFERROR(I7*3,0)-IFERROR(J7*1,0)+IFERROR(K7*4,0)+IFERROR(N7*1,0)+IFERROR(O7*1,0)-IFERROR(L7*2,0)-IFERROR(M7*2,0),IF(B7="DEF",2+IFERROR(F7*6,0)+IFERROR(G7*6,0)+IFERROR(H7*6,0)+IFERROR(I7*3,0)-IFERROR(J7*1,0)+IFERROR(K7*4,0)-IFERROR(L7*2,0)-IFERROR(M7*2,0)+IFERROR(P7*2,0),IF(B7="MID",2+IFERROR(F7*5,0)+IFERROR(G7*5,0)+IFERROR(H7*5,0)+IFERROR(I7*3,0)-IFERROR(J7*1,0)+IFERROR(K7*1,0)+IFERROR(Q7*2,0),IF(B7="FWD",2+IFERROR(F7*4,0)+IFERROR(G7*4,0)+IFERROR(H7*4,0)+IFERROR(I7*3,0)-IFERROR(J7*1,0),"ERROR")))),0) -> 4.5333898 | S7: =MAX(0, MIN(1, -0.021039 + 0.023522 * R7)) -> 0.085595394 | T7: =R7+S7*2 -> 4.7045805 | U7: =VLOOKUP($C7,'Team Fixtures'!$A$2:$Q$21,2,FALSE) -> 0.88924459 | V7: =VLOOKUP($C7,'Team Fixtures'!$A$2:$Q$21,4,FALSE) -> 0.028011204 | W7: =VLOOKUP($C7,'Team Fixtures'!$A$2:$Q$21,5,FALSE) -> 0.86123338 | X7: =VLOOKUP($C7,'Team Fixtures'!$A$2:$Q$21,6,FALSE) -> H | Y7: =R7/(2.926+0.578*U7-0.576*V7-0.561*W7+0.469*IF(X7="H",1,0)) -> 1.329558 | Z7: =VLOOKUP($C7,'Team Fixtures'!$A$2:$Q$21,2,FALSE) -> 0.88924459 | AA7: =VLOOKUP($C7,'Team Fixtures'!$A$2:$Q$21,8,FALSE) -> 0.89678056 | AB7: =VLOOKUP($C7,'Team Fixtures'!$A$2:$Q$21,9,FALSE) -> -0.0075359711 | AC7: =VLOOKUP($C7,'Team Fixtures'!$A$2:$Q$21,10,FALSE) -> A | AD7: =IFERROR((2.926+0.578*Z7-0.576*AA7-0.561*AB7+0.469*IF(AC7="H",1,0))*$Y7,0) -> 3.8925009 | AE7: =MAX(0, MIN(1, -0.021039 + 0.023522 * AD7)) -> 0.070520406 | AF7: =AD7+AE7*2 -> 4.0335417 | AG7: =VLOOKUP($C7,'Team Fixtures'!$A$2:$Q$21,2,FALSE) -> 0.88924459 | AH7: =VLOOKUP($C7,'Team Fixtures'!$A$2:$Q$21,12,FALSE) -> 0.10582011 | AI7: =VLOOKUP($C7,'Team Fixtures'!$A$2:$Q$21,13,FALSE) -> 0.78342448 | AJ7: =VLOOKUP($C7,'Team Fixtures'!$A$2:$Q$21,14,FALSE) -> H | AK7: =IFERROR((2.926+0.578*AG7-0.576*AH7-0.561*AI7+0.469*IF(AJ7="H",1,0))*$Y7,0) -> 4.531838 | AL7: =MAX(0, MIN(1, -0.021039 + 0.023522 * AK7)) -> 0.085558893 | AM7: =AK7+AL7*2 -> 4.7029558 | AN7: =VLOOKUP($C7,'Team Fixtures'!$A$2:$Q$21,2,FALSE) -> 0.88924459 | AO7: =VLOOKUP($C7,'Team Fixtures'!$A$2:$Q$21,16,FALSE) -> 0.87939146 | AP7: =VLOOKUP($C7,'Team Fixtures'!$A$2:$Q$21,17,FALSE) -> 0.0098531256 | AQ7: =VLOOKUP($C7,'Team Fixtures'!$A$2:$V$21,18,FALSE) -> H | AR7: =IFERROR((2.926+0.578*AN7-0.576*AO7-0.561*AP7+0.469*IF(AQ7="H",1,0))*$Y7,0) -> 4.5164104 | AS7: =MAX(0, MIN(1, -0.021039 + 0.023522 * AR7)) -> 0.085196005 | AT7: =AR7+AS7*2 -> 4.6868024 | AU7: =VLOOKUP($C7,'Team Fixtures'!$A$2:$Q$21,2,FALSE) -> 0.88924459 | AV7: =VLOOKUP($C7,'Team Fixtures'!$A$2:$V$21,20,FALSE) -> 0.50125313 | AW7: =VLOOKUP($C7,'Team Fixtures'!$A$2:$V$21,21,FALSE) -> 0.38799145 | AX7: =VLOOKUP($C7,'Team Fixtures'!$A$2:$V$21,22,FALSE) -> A | AY7: =IFERROR((2.926+0.578*AU7-0.576*AV7-0.561*AW7+0.469*IF(AX7="H",1,0))*$Y7,0) -> 3.900389 | AZ7: =MAX(0, MIN(1, -0.021039 + 0.023522 * AY7)) -> 0.070705951 | BA7: =AY7+AZ7*2 -> 4.0418009 | BB7: =IFERROR(T7*1+AF7*0.85+AM7*0.7+AT7*0.55+BA7*0.4,0) -> 15.619622
A8: ='Players Full'!CU8 -> Riccardo Calafiori | B8: =VLOOKUP(_xlfn.CONCAT('Players Full'!AK8,'Players Full'!BV8),'Players Summarised'!$A$1:$T$1000,20,0) -> DEF | C8: =VLOOKUP('Players Full'!CF8,Teams!$A$1:$G$21,6,0) -> Arsenal | D8: ='Players Full'!BD8/10 -> 5.5 | E8: =IFERROR(VLOOKUP($A8,'Starting Lineups'!$A$2:$C$510,3,FALSE),0) -> 0 | F8: =VLOOKUP(A8,'Score & Assist'!$A$1:$G$2000,6,0) -> 0.11204482 | G8: =IF(F8<0.3, 0.01,IF(F8=0.3,0.03,IF(F8<0.5,0.05,IF(F8<0.55,0.06,IF(F8<0.57,0.1,IF(F8<0.58,0.11,IF(F8<0.59,0.12,IF(F8<0.6,0.15,0.28)))))))) -> 0.01 | H8: =IF(F8<0.3,0,IF(F8<0.55,0.01,IF(F8<0.59,0.02,IF(F8<0.6,0.03,0.11)))) -> 0 | I8: =VLOOKUP(A8,'Score & Assist'!$A$1:$G$2000,7,0) -> 0.13605442 | J8: =VLOOKUP(A8,'Yellow Card'!$C$1:$E$987,3,0) -> 0.17316017 | K8: =VLOOKUP(C8,'Team Clean Sheet'!$C$2:$F$21,4,0) -> 0.5 | L8: =VLOOKUP(C8,'Team Total Goals'!$D$2:$N$21,10,0) -> 0.17168675 | M8: =VLOOKUP(C8,'Team Total Goals'!$D$2:$N$21,11,0) -> 0.01926849 | N8: =VLOOKUP(A8,'Goalkeeper Saves'!$D$2:$N$15,10,0) -> #N/A | O8: =VLOOKUP(A8,'Goalkeeper Saves'!$D$2:$N$15,11,0) -> #N/A | P8: =IF(B8="DEF",IFERROR(VLOOKUP(A8,'Defensive Contribution - DEF'!A8:H504,8,FALSE),'Defensive Contribution - DEF'!K$2),0) -> 0.11357041 | Q8: =IF(B8="MID",IFERROR(VLOOKUP(A8,'Defensive Contribution - MID'!A$2:I$500,9,FALSE),'Defensive Contribution - MID'!L$2),0) -> 0 | R8: =IFERROR(IFERROR(E8,0)*IF(B8="GK",2+IFERROR(F8*10,0)+IFERROR(G8*10,0)+IFERROR(H8*10,0)+IFERROR(I8*3,0)-IFERROR(J8*1,0)+IFERROR(K8*4,0)+IFERROR(N8*1,0)+IFERROR(O8*1,0)-IFERROR(L8*2,0)-IFERROR(M8*2,0),IF(B8="DEF",2+IFERROR(F8*6,0)+IFERROR(G8*6,0)+IFERROR(H8*6,0)+IFERROR(I8*3,0)-IFERROR(J8*1,0)+IFERROR(K8*4,0)-IFERROR(L8*2,0)-IFERROR(M8*2,0)+IFERROR(P8*2,0),IF(B8="MID",2+IFERROR(F8*5,0)+IFERROR(G8*5,0)+IFERROR(H8*5,0)+IFERROR(I8*3,0)-IFERROR(J8*1,0)+IFERROR(K8*1,0)+IFERROR(Q8*2,0),IF(B8="FWD",2+IFERROR(F8*4,0)+IFERROR(G8*4,0)+IFERROR(H8*4,0)+IFERROR(I8*3,0)-IFERROR(J8*1,0),"ERROR")))),0) -> 0 | S8: =MAX(0, MIN(1, -0.021039 + 0.023522 * R8)) -> 0 | T8: =R8+S8*2 -> 0 | U8: =VLOOKUP($C8,'Team Fixtures'!$A$2:$Q$21,2,FALSE) -> 0.88924459 | V8: =VLOOKUP($C8,'Team Fixtures'!$A$2:$Q$21,4,FALSE) -> 0.028011204 | W8: =VLOOKUP($C8,'Team Fixtures'!$A$2:$Q$21,5,FALSE) -> 0.86123338 | X8: =VLOOKUP($C8,'Team Fixtures'!$A$2:$Q$21,6,FALSE) -> H | Y8: =R8/(2.926+0.578*U8-0.576*V8-0.561*W8+0.469*IF(X8="H",1,0)) -> 0 | Z8: =VLOOKUP($C8,'Team Fixtures'!$A$2:$Q$21,2,FALSE) -> 0.88924459 | AA8: =VLOOKUP($C8,'Team Fixtures'!$A$2:$Q$21,8,FALSE) -> 0.89678056 | AB8: =VLOOKUP($C8,'Team Fixtures'!$A$2:$Q$21,9,FALSE) -> -0.0075359711 | AC8: =VLOOKUP($C8,'Team Fixtures'!$A$2:$Q$21,10,FALSE) -> A | AD8: =IFERROR((2.926+0.578*Z8-0.576*AA8-0.561*AB8+0.469*IF(AC8="H",1,0))*$Y8,0) -> 0 | AE8: =MAX(0, MIN(1, -0.021039 + 0.023522 * AD8)) -> 0 | AF8: =AD8+AE8*2 -> 0 | AG8: =VLOOKUP($C8,'Team Fixtures'!$A$2:$Q$21,2,FALSE) -> 0.88924459 | AH8: =VLOOKUP($C8,'Team Fixtures'!$A$2:$Q$21,12,FALSE) -> 0.10582011 | AI8: =VLOOKUP($C8,'Team Fixtures'!$A$2:$Q$21,13,FALSE) -> 0.78342448 | AJ8: =VLOOKUP($C8,'Team Fixtures'!$A$2:$Q$21,14,FALSE) -> H | AK8: =IFERROR((2.926+0.578*AG8-0.576*AH8-0.561*AI8+0.469*IF(AJ8="H",1,0))*$Y8,0) -> 0 | AL8: =MAX(0, MIN(1, -0.021039 + 0.023522 * AK8)) -> 0 | AM8: =AK8+AL8*2 -> 0 | AN8: =VLOOKUP($C8,'Team Fixtures'!$A$2:$Q$21,2,FALSE) -> 0.88924459 | AO8: =VLOOKUP($C8,'Team Fixtures'!$A$2:$Q$21,16,FALSE) -> 0.87939146 | AP8: =VLOOKUP($C8,'Team Fixtures'!$A$2:$Q$21,17,FALSE) -> 0.0098531256 | AQ8: =VLOOKUP($C8,'Team Fixtures'!$A$2:$V$21,18,FALSE) -> H | AR8: =IFERROR((2.926+0.578*AN8-0.576*AO8-0.561*AP8+0.469*IF(AQ8="H",1,0))*$Y8,0) -> 0 | AS8: =MAX(0, MIN(1, -0.021039 + 0.023522 * AR8)) -> 0 | AT8: =AR8+AS8*2 -> 0 | AU8: =VLOOKUP($C8,'Team Fixtures'!$A$2:$Q$21,2,FALSE) -> 0.88924459 | AV8: =VLOOKUP($C8,'Team Fixtures'!$A$2:$V$21,20,FALSE) -> 0.50125313 | AW8: =VLOOKUP($C8,'Team Fixtures'!$A$2:$V$21,21,FALSE) -> 0.38799145 | AX8: =VLOOKUP($C8,'Team Fixtures'!$A$2:$V$21,22,FALSE) -> A | AY8: =IFERROR((2.926+0.578*AU8-0.576*AV8-0.561*AW8+0.469*IF(AX8="H",1,0))*$Y8,0) -> 0 | AZ8: =MAX(0, MIN(1, -0.021039 + 0.023522 * AY8)) -> 0 | BA8: =AY8+AZ8*2 -> 0 | BB8: =IFERROR(T8*1+AF8*0.85+AM8*0.7+AT8*0.55+BA8*0.4,0) -> 0
A9: ='Players Full'!CU9 -> Jurrian Timber | B9: =VLOOKUP(_xlfn.CONCAT('Players Full'!AK9,'Players Full'!BV9),'Players Summarised'!$A$1:$T$1000,20,0) -> DEF | C9: =VLOOKUP('Players Full'!CF9,Teams!$A$1:$G$21,6,0) -> Arsenal | D9: ='Players Full'!BD9/10 -> 5.5 | E9: =IFERROR(VLOOKUP($A9,'Starting Lineups'!$A$2:$C$510,3,FALSE),0) -> 0 | F9: =VLOOKUP(A9,'Score & Assist'!$A$1:$G$2000,6,0) -> #N/A | G9: =IF(F9<0.3, 0.01,IF(F9=0.3,0.03,IF(F9<0.5,0.05,IF(F9<0.55,0.06,IF(F9<0.57,0.1,IF(F9<0.58,0.11,IF(F9<0.59,0.12,IF(F9<0.6,0.15,0.28)))))))) -> #N/A | H9: =IF(F9<0.3,0,IF(F9<0.55,0.01,IF(F9<0.59,0.02,IF(F9<0.6,0.03,0.11)))) -> #N/A | I9: =VLOOKUP(A9,'Score & Assist'!$A$1:$G$2000,7,0) -> #N/A | J9: =VLOOKUP(A9,'Yellow Card'!$C$1:$E$987,3,0) -> #N/A | K9: =VLOOKUP(C9,'Team Clean Sheet'!$C$2:$F$21,4,0) -> 0.5 | L9: =VLOOKUP(C9,'Team Total Goals'!$D$2:$N$21,10,0) -> 0.17168675 | M9: =VLOOKUP(C9,'Team Total Goals'!$D$2:$N$21,11,0) -> 0.01926849 | N9: =VLOOKUP(A9,'Goalkeeper Saves'!$D$2:$N$15,10,0) -> #N/A | O9: =VLOOKUP(A9,'Goalkeeper Saves'!$D$2:$N$15,11,0) -> #N/A | P9: =IF(B9="DEF",IFERROR(VLOOKUP(A9,'Defensive Contribution - DEF'!A9:H505,8,FALSE),'Defensive Contribution - DEF'!K$2),0) -> 0.2915234 | Q9: =IF(B9="MID",IFERROR(VLOOKUP(A9,'Defensive Contribution - MID'!A$2:I$500,9,FALSE),'Defensive Contribution - MID'!L$2),0) -> 0 | R9: =IFERROR(IFERROR(E9,0)*IF(B9="GK",2+IFERROR(F9*10,0)+IFERROR(G9*10,0)+IFERROR(H9*10,0)+IFERROR(I9*3,0)-IFERROR(J9*1,0)+IFERROR(K9*4,0)+IFERROR(N9*1,0)+IFERROR(O9*1,0)-IFERROR(L9*2,0)-IFERROR(M9*2,0),IF(B9="DEF",2+IFERROR(F9*6,0)+IFERROR(G9*6,0)+IFERROR(H9*6,0)+IFERROR(I9*3,0)-IFERROR(J9*1,0)+IFERROR(K9*4,0)-IFERROR(L9*2,0)-IFERROR(M9*2,0)+IFERROR(P9*2,0),IF(B9="MID",2+IFERROR(F9*5,0)+IFERROR(G9*5,0)+IFERROR(H9*5,0)+IFERROR(I9*3,0)-IFERROR(J9*1,0)+IFERROR(K9*1,0)+IFERROR(Q9*2,0),IF(B9="FWD",2+IFERROR(F9*4,0)+IFERROR(G9*4,0)+IFERROR(H9*4,0)+IFERROR(I9*3,0)-IFERROR(J9*1,0),"ERROR")))),0) -> 0 | S9: =MAX(0, MIN(1, -0.021039 + 0.023522 * R9)) -> 0 | T9: =R9+S9*2 -> 0 | U9: =VLOOKUP($C9,'Team Fixtures'!$A$2:$Q$21,2,FALSE) -> 0.88924459 | V9: =VLOOKUP($C9,'Team Fixtures'!$A$2:$Q$21,4,FALSE) -> 0.028011204 | W9: =VLOOKUP($C9,'Team Fixtures'!$A$2:$Q$21,5,FALSE) -> 0.86123338 | X9: =VLOOKUP($C9,'Team Fixtures'!$A$2:$Q$21,6,FALSE) -> H | Y9: =R9/(2.926+0.578*U9-0.576*V9-0.561*W9+0.469*IF(X9="H",1,0)) -> 0 | Z9: =VLOOKUP($C9,'Team Fixtures'!$A$2:$Q$21,2,FALSE) -> 0.88924459 | AA9: =VLOOKUP($C9,'Team Fixtures'!$A$2:$Q$21,8,FALSE) -> 0.89678056 | AB9: =VLOOKUP($C9,'Team Fixtures'!$A$2:$Q$21,9,FALSE) -> -0.0075359711 | AC9: =VLOOKUP($C9,'Team Fixtures'!$A$2:$Q$21,10,FALSE) -> A | AD9: =IFERROR((2.926+0.578*Z9-0.576*AA9-0.561*AB9+0.469*IF(AC9="H",1,0))*$Y9,0) -> 0 | AE9: =MAX(0, MIN(1, -0.021039 + 0.023522 * AD9)) -> 0 | AF9: =AD9+AE9*2 -> 0 | AG9: =VLOOKUP($C9,'Team Fixtures'!$A$2:$Q$21,2,FALSE) -> 0.88924459 | AH9: =VLOOKUP($C9,'Team Fixtures'!$A$2:$Q$21,12,FALSE) -> 0.10582011 | AI9: =VLOOKUP($C9,'Team Fixtures'!$A$2:$Q$21,13,FALSE) -> 0.78342448 | AJ9: =VLOOKUP($C9,'Team Fixtures'!$A$2:$Q$21,14,FALSE) -> H | AK9: =IFERROR((2.926+0.578*AG9-0.576*AH9-0.561*AI9+0.469*IF(AJ9="H",1,0))*$Y9,0) -> 0 | AL9: =MAX(0, MIN(1, -0.021039 + 0.023522 * AK9)) -> 0 | AM9: =AK9+AL9*2 -> 0 | AN9: =VLOOKUP($C9,'Team Fixtures'!$A$2:$Q$21,2,FALSE) -> 0.88924459 | AO9: =VLOOKUP($C9,'Team Fixtures'!$A$2:$Q$21,16,FALSE) -> 0.87939146 | AP9: =VLOOKUP($C9,'Team Fixtures'!$A$2:$Q$21,17,FALSE) -> 0.0098531256 | AQ9: =VLOOKUP($C9,'Team Fixtures'!$A$2:$V$21,18,FALSE) -> H | AR9: =IFERROR((2.926+0.578*AN9-0.576*AO9-0.561*AP9+0.469*IF(AQ9="H",1,0))*$Y9,0) -> 0 | AS9: =MAX(0, MIN(1, -0.021039 + 0.023522 * AR9)) -> 0 | AT9: =AR9+AS9*2 -> 0 | AU9: =VLOOKUP($C9,'Team Fixtures'!$A$2:$Q$21,2,FALSE) -> 0.88924459 | AV9: =VLOOKUP($C9,'Team Fixtures'!$A$2:$V$21,20,FALSE) -> 0.50125313 | AW9: =VLOOKUP($C9,'Team Fixtures'!$A$2:$V$21,21,FALSE) -> 0.38799145 | AX9: =VLOOKUP($C9,'Team Fixtures'!$A$2:$V$21,22,FALSE) -> A | AY9: =IFERROR((2.926+0.578*AU9-0.576*AV9-0.561*AW9+0.469*IF(AX9="H",1,0))*$Y9,0) -> 0 | AZ9: =MAX(0, MIN(1, -0.021039 + 0.023522 * AY9)) -> 0 | BA9: =AY9+AZ9*2 -> 0 | BB9: =IFERROR(T9*1+AF9*0.85+AM9*0.7+AT9*0.55+BA9*0.4,0) -> 0
A10: ='Players Full'!CU10 -> Jakub Kiwior | B10: =VLOOKUP(_xlfn.CONCAT('Players Full'!AK10,'Players Full'!BV10),'Players Summarised'!$A$1:$T$1000,20,0) -> DEF | C10: =VLOOKUP('Players Full'!CF10,Teams!$A$1:$G$21,6,0) -> Arsenal | D10: ='Players Full'!BD10/10 -> 5.5 | E10: =IFERROR(VLOOKUP($A10,'Starting Lineups'!$A$2:$C$510,3,FALSE),0) -> 0 | F10: =VLOOKUP(A10,'Score & Assist'!$A$1:$G$2000,6,0) -> 0.10025063 | G10: =IF(F10<0.3, 0.01,IF(F10=0.3,0.03,IF(F10<0.5,0.05,IF(F10<0.55,0.06,IF(F10<0.57,0.1,IF(F10<0.58,0.11,IF(F10<0.59,0.12,IF(F10<0.6,0.15,0.28)))))))) -> 0.01 | H10: =IF(F10<0.3,0,IF(F10<0.55,0.01,IF(F10<0.59,0.02,IF(F10<0.6,0.03,0.11)))) -> 0 | I10: =VLOOKUP(A10,'Score & Assist'!$A$1:$G$2000,7,0) -> 0.10582011 | J10: =VLOOKUP(A10,'Yellow Card'!$C$1:$E$987,3,0) -> 0.13605442 | K10: =VLOOKUP(C10,'Team Clean Sheet'!$C$2:$F$21,4,0) -> 0.5 | L10: =VLOOKUP(C10,'Team Total Goals'!$D$2:$N$21,10,0) -> 0.17168675 | M10: =VLOOKUP(C10,'Team Total Goals'!$D$2:$N$21,11,0) -> 0.01926849 | N10: =VLOOKUP(A10,'Goalkeeper Saves'!$D$2:$N$15,10,0) -> #N/A | O10: =VLOOKUP(A10,'Goalkeeper Saves'!$D$2:$N$15,11,0) -> #N/A | P10: =IF(B10="DEF",IFERROR(VLOOKUP(A10,'Defensive Contribution - DEF'!A10:H506,8,FALSE),'Defensive Contribution - DEF'!K$2),0) -> 0.22344252 | Q10: =IF(B10="MID",IFERROR(VLOOKUP(A10,'Defensive Contribution - MID'!A$2:I$500,9,FALSE),'Defensive Contribution - MID'!L$2),0) -> 0 | R10: =IFERROR(IFERROR(E10,0)*IF(B10="GK",2+IFERROR(F10*10,0)+IFERROR(G10*10,0)+IFERROR(H10*10,0)+IFERROR(I10*3,0)-IFERROR(J10*1,0)+IFERROR(K10*4,0)+IFERROR(N10*1,0)+IFERROR(O10*1,0)-IFERROR(L10*2,0)-IFERROR(M10*2,0),IF(B10="DEF",2+IFERROR(F10*6,0)+IFERROR(G10*6,0)+IFERROR(H10*6,0)+IFERROR(I10*3,0)-IFERROR(J10*1,0)+IFERROR(K10*4,0)-IFERROR(L10*2,0)-IFERROR(M10*2,0)+IFERROR(P10*2,0),IF(B10="MID",2+IFERROR(F10*5,0)+IFERROR(G10*5,0)+IFERROR(H10*5,0)+IFERROR(I10*3,0)-IFERROR(J10*1,0)+IFERROR(K10*1,0)+IFERROR(Q10*2,0),IF(B10="FWD",2+IFERROR(F10*4,0)+IFERROR(G10*4,0)+IFERROR(H10*4,0)+IFERROR(I10*3,0)-IFERROR(J10*1,0),"ERROR")))),0) -> 0 | S10: =MAX(0, MIN(1, -0.021039 + 0.023522 * R10)) -> 0 | T10: =R10+S10*2 -> 0 | U10: =VLOOKUP($C10,'Team Fixtures'!$A$2:$Q$21,2,FALSE) -> 0.88924459 | V10: =VLOOKUP($C10,'Team Fixtures'!$A$2:$Q$21,4,FALSE) -> 0.028011204 | W10: =VLOOKUP($C10,'Team Fixtures'!$A$2:$Q$21,5,FALSE) -> 0.86123338 | X10: =VLOOKUP($C10,'Team Fixtures'!$A$2:$Q$21,6,FALSE) -> H | Y10: =R10/(2.926+0.578*U10-0.576*V10-0.561*W10+0.469*IF(X10="H",1,0)) -> 0 | Z10: =VLOOKUP($C10,'Team Fixtures'!$A$2:$Q$21,2,FALSE) -> 0.88924459 | AA10: =VLOOKUP($C10,'Team Fixtures'!$A$2:$Q$21,8,FALSE) -> 0.89678056 | AB10: =VLOOKUP($C10,'Team Fixtures'!$A$2:$Q$21,9,FALSE) -> -0.0075359711 | AC10: =VLOOKUP($C10,'Team Fixtures'!$A$2:$Q$21,10,FALSE) -> A | AD10: =IFERROR((2.926+0.578*Z10-0.576*AA10-0.561*AB10+0.469*IF(AC10="H",1,0))*$Y10,0) -> 0 | AE10: =MAX(0, MIN(1, -0.021039 + 0.023522 * AD10)) -> 0 | AF10: =AD10+AE10*2 -> 0 | AG10: =VLOOKUP($C10,'Team Fixtures'!$A$2:$Q$21,2,FALSE) -> 0.88924459 | AH10: =VLOOKUP($C10,'Team Fixtures'!$A$2:$Q$21,12,FALSE) -> 0.10582011 | AI10: =VLOOKUP($C10,'Team Fixtures'!$A$2:$Q$21,13,FALSE) -> 0.78342448 | AJ10: =VLOOKUP($C10,'Team Fixtures'!$A$2:$Q$21,14,FALSE) -> H | AK10: =IFERROR((2.926+0.578*AG10-0.576*AH10-0.561*AI10+0.469*IF(AJ10="H",1,0))*$Y10,0) -> 0 | AL10: =MAX(0, MIN(1, -0.021039 + 0.023522 * AK10)) -> 0 | AM10: =AK10+AL10*2 -> 0 | AN10: =VLOOKUP($C10,'Team Fixtures'!$A$2:$Q$21,2,FALSE) -> 0.88924459 | AO10: =VLOOKUP($C10,'Team Fixtures'!$A$2:$Q$21,16,FALSE) -> 0.87939146 | AP10: =VLOOKUP($C10,'Team Fixtures'!$A$2:$Q$21,17,FALSE) -> 0.0098531256 | AQ10: =VLOOKUP($C10,'Team Fixtures'!$A$2:$V$21,18,FALSE) -> H | AR10: =IFERROR((2.926+0.578*AN10-0.576*AO10-0.561*AP10+0.469*IF(AQ10="H",1,0))*$Y10,0) -> 0 | AS10: =MAX(0, MIN(1, -0.021039 + 0.023522 * AR10)) -> 0 | AT10: =AR10+AS10*2 -> 0 | AU10: =VLOOKUP($C10,'Team Fixtures'!$A$2:$Q$21,2,FALSE) -> 0.88924459 | AV10: =VLOOKUP($C10,'Team Fixtures'!$A$2:$V$21,20,FALSE) -> 0.50125313 | AW10: =VLOOKUP($C10,'Team Fixtures'!$A$2:$V$21,21,FALSE) -> 0.38799145 | AX10: =VLOOKUP($C10,'Team Fixtures'!$A$2:$V$21,22,FALSE) -> A | AY10: =IFERROR((2.926+0.578*AU10-0.576*AV10-0.561*AW10+0.469*IF(AX10="H",1,0))*$Y10,0) -> 0 | AZ10: =MAX(0, MIN(1, -0.021039 + 0.023522 * AY10)) -> 0 | BA10: =AY10+AZ10*2 -> 0 | BB10: =IFERROR(T10*1+AF10*0.85+AM10*0.7+AT10*0.55+BA10*0.4,0) -> 0
A11: ='Players Full'!CU11 -> Myles Lewis-Skelly | B11: =VLOOKUP(_xlfn.CONCAT('Players Full'!AK11,'Players Full'!BV11),'Players Summarised'!$A$1:$T$1000,20,0) -> DEF | C11: =VLOOKUP('Players Full'!CF11,Teams!$A$1:$G$21,6,0) -> Arsenal | D11: ='Players Full'!BD11/10 -> 5.5 | E11: =IFERROR(VLOOKUP($A11,'Starting Lineups'!$A$2:$C$510,3,FALSE),0) -> 1 | F11: =VLOOKUP(A11,'Score & Assist'!$A$1:$G$2000,6,0) -> 0.13605442 | G11: =IF(F11<0.3, 0.01,IF(F11=0.3,0.03,IF(F11<0.5,0.05,IF(F11<0.55,0.06,IF(F11<0.57,0.1,IF(F11<0.58,0.11,IF(F11<0.59,0.12,IF(F11<0.6,0.15,0.28)))))))) -> 0.01 | H11: =IF(F11<0.3,0,IF(F11<0.55,0.01,IF(F11<0.59,0.02,IF(F11<0.6,0.03,0.11)))) -> 0 | I11: =VLOOKUP(A11,'Score & Assist'!$A$1:$G$2000,7,0) -> 0.095238095 | J11: =VLOOKUP(A11,'Yellow Card'!$C$1:$E$987,3,0) -> 0.17316017 | K11: =VLOOKUP(C11,'Team Clean Sheet'!$C$2:$F$21,4,0) -> 0.5 | L11: =VLOOKUP(C11,'Team Total Goals'!$D$2:$N$21,10,0) -> 0.17168675 | M11: =VLOOKUP(C11,'Team Total Goals'!$D$2:$N$21,11,0) -> 0.01926849 | N11: =VLOOKUP(A11,'Goalkeeper Saves'!$D$2:$N$15,10,0) -> #N/A | O11: =VLOOKUP(A11,'Goalkeeper Saves'!$D$2:$N$15,11,0) -> #N/A | P11: =IF(B11="DEF",IFERROR(VLOOKUP(A11,'Defensive Contribution - DEF'!A11:H507,8,FALSE),'Defensive Contribution - DEF'!K$2),0) -> 0.013437179 | Q11: =IF(B11="MID",IFERROR(VLOOKUP(A11,'Defensive Contribution - MID'!A$2:I$500,9,FALSE),'Defensive Contribution - MID'!L$2),0) -> 0 | R11: =IFERROR(IFERROR(E11,0)*IF(B11="GK",2+IFERROR(F11*10,0)+IFERROR(G11*10,0)+IFERROR(H11*10,0)+IFERROR(I11*3,0)-IFERROR(J11*1,0)+IFERROR(K11*4,0)+IFERROR(N11*1,0)+IFERROR(O11*1,0)-IFERROR(L11*2,0)-IFERROR(M11*2,0),IF(B11="DEF",2+IFERROR(F11*6,0)+IFERROR(G11*6,0)+IFERROR(H11*6,0)+IFERROR(I11*3,0)-IFERROR(J11*1,0)+IFERROR(K11*4,0)-IFERROR(L11*2,0)-IFERROR(M11*2,0)+IFERROR(P11*2,0),IF(B11="MID",2+IFERROR(F11*5,0)+IFERROR(G11*5,0)+IFERROR(H11*5,0)+IFERROR(I11*3,0)-IFERROR(J11*1,0)+IFERROR(K11*1,0)+IFERROR(Q11*2,0),IF(B11="FWD",2+IFERROR(F11*4,0)+IFERROR(G11*4,0)+IFERROR(H11*4,0)+IFERROR(I11*3,0)-IFERROR(J11*1,0),"ERROR")))),0) -> 4.6338445 | S11: =MAX(0, MIN(1, -0.021039 + 0.023522 * R11)) -> 0.087958291 | T11: =R11+S11*2 -> 4.8097611 | U11: =VLOOKUP($C11,'Team Fixtures'!$A$2:$Q$21,2,FALSE) -> 0.88924459 | V11: =VLOOKUP($C11,'Team Fixtures'!$A$2:$Q$21,4,FALSE) -> 0.028011204 | W11: =VLOOKUP($C11,'Team Fixtures'!$A$2:$Q$21,5,FALSE) -> 0.86123338 | X11: =VLOOKUP($C11,'Team Fixtures'!$A$2:$Q$21,6,FALSE) -> H | Y11: =R11/(2.926+0.578*U11-0.576*V11-0.561*W11+0.469*IF(X11="H",1,0)) -> 1.3590194 | Z11: =VLOOKUP($C11,'Team Fixtures'!$A$2:$Q$21,2,FALSE) -> 0.88924459 | AA11: =VLOOKUP($C11,'Team Fixtures'!$A$2:$Q$21,8,FALSE) -> 0.89678056 | AB11: =VLOOKUP($C11,'Team Fixtures'!$A$2:$Q$21,9,FALSE) -> -0.0075359711 | AC11: =VLOOKUP($C11,'Team Fixtures'!$A$2:$Q$21,10,FALSE) -> A | AD11: =IFERROR((2.926+0.578*Z11-0.576*AA11-0.561*AB11+0.469*IF(AC11="H",1,0))*$Y11,0) -> 3.9787543 | AE11: =MAX(0, MIN(1, -0.021039 + 0.023522 * AD11)) -> 0.072549258 | AF11: =AD11+AE11*2 -> 4.1238528 | AG11: =VLOOKUP($C11,'Team Fixtures'!$A$2:$Q$21,2,FALSE) -> 0.88924459 | AH11: =VLOOKUP($C11,'Team Fixtures'!$A$2:$Q$21,12,FALSE) -> 0.10582011 | AI11: =VLOOKUP($C11,'Team Fixtures'!$A$2:$Q$21,13,FALSE) -> 0.78342448 | AJ11: =VLOOKUP($C11,'Team Fixtures'!$A$2:$Q$21,14,FALSE) -> H | AK11: =IFERROR((2.926+0.578*AG11-0.576*AH11-0.561*AI11+0.469*IF(AJ11="H",1,0))*$Y11,0) -> 4.6322584 | AL11: =MAX(0, MIN(1, -0.021039 + 0.023522 * AK11)) -> 0.087920981 | AM11: =AK11+AL11*2 -> 4.8081003 | AN11: =VLOOKUP($C11,'Team Fixtures'!$A$2:$Q$21,2,FALSE) -> 0.88924459 | AO11: =VLOOKUP($C11,'Team Fixtures'!$A$2:$Q$21,16,FALSE) -> 0.87939146 | AP11: =VLOOKUP($C11,'Team Fixtures'!$A$2:$Q$21,17,FALSE) -> 0.0098531256 | AQ11: =VLOOKUP($C11,'Team Fixtures'!$A$2:$V$21,18,FALSE) -> H | AR11: =IFERROR((2.926+0.578*AN11-0.576*AO11-0.561*AP11+0.469*IF(AQ11="H",1,0))*$Y11,0) -> 4.6164889 | AS11: =MAX(0, MIN(1, -0.021039 + 0.023522 * AR11)) -> 0.087550052 | AT11: =AR11+AS11*2 -> 4.791589 | AU11: =VLOOKUP($C11,'Team Fixtures'!$A$2:$Q$21,2,FALSE) -> 0.88924459 | AV11: =VLOOKUP($C11,'Team Fixtures'!$A$2:$V$21,20,FALSE) -> 0.50125313 | AW11: =VLOOKUP($C11,'Team Fixtures'!$A$2:$V$21,21,FALSE) -> 0.38799145 | AX11: =VLOOKUP($C11,'Team Fixtures'!$A$2:$V$21,22,FALSE) -> A | AY11: =IFERROR((2.926+0.578*AU11-0.576*AV11-0.561*AW11+0.469*IF(AX11="H",1,0))*$Y11,0) -> 3.9868172 | AZ11: =MAX(0, MIN(1, -0.021039 + 0.023522 * AY11)) -> 0.072738915 | BA11: =AY11+AZ11*2 -> 4.1322951 | BB11: =IFERROR(T11*1+AF11*0.85+AM11*0.7+AT11*0.55+BA11*0.4,0) -> 15.968998
A12: ='Players Full'!CU12 -> Ben White | B12: =VLOOKUP(_xlfn.CONCAT('Players Full'!AK12,'Players Full'!BV12),'Players Summarised'!$A$1:$T$1000,20,0) -> DEF | C12: =VLOOKUP('Players Full'!CF12,Teams!$A$1:$G$21,6,0) -> Arsenal | D12: ='Players Full'!BD12/10 -> 5.5 | E12: =IFERROR(VLOOKUP($A12,'Starting Lineups'!$A$2:$C$510,3,FALSE),0) -> 1 | F12: =VLOOKUP(A12,'Score & Assist'!$A$1:$G$2000,6,0) -> 0.10025063 | G12: =IF(F12<0.3, 0.01,IF(F12=0.3,0.03,IF(F12<0.5,0.05,IF(F12<0.55,0.06,IF(F12<0.57,0.1,IF(F12<0.58,0.11,IF(F12<0.59,0.12,IF(F12<0.6,0.15,0.28)))))))) -> 0.01 | H12: =IF(F12<0.3,0,IF(F12<0.55,0.01,IF(F12<0.59,0.02,IF(F12<0.6,0.03,0.11)))) -> 0 | I12: =VLOOKUP(A12,'Score & Assist'!$A$1:$G$2000,7,0) -> 0.11904762 | J12: =VLOOKUP(A12,'Yellow Card'!$C$1:$E$987,3,0) -> 0.14652015 | K12: =VLOOKUP(C12,'Team Clean Sheet'!$C$2:$F$21,4,0) -> 0.5 | L12: =VLOOKUP(C12,'Team Total Goals'!$D$2:$N$21,10,0) -> 0.17168675 | M12: =VLOOKUP(C12,'Team Total Goals'!$D$2:$N$21,11,0) -> 0.01926849 | N12: =VLOOKUP(A12,'Goalkeeper Saves'!$D$2:$N$15,10,0) -> #N/A | O12: =VLOOKUP(A12,'Goalkeeper Saves'!$D$2:$N$15,11,0) -> #N/A | P12: =IF(B12="DEF",IFERROR(VLOOKUP(A12,'Defensive Contribution - DEF'!A12:H508,8,FALSE),'Defensive Contribution - DEF'!K$2),0) -> 0.11854733 | Q12: =IF(B12="MID",IFERROR(VLOOKUP(A12,'Defensive Contribution - MID'!A$2:I$500,9,FALSE),'Defensive Contribution - MID'!L$2),0) -> 0 | R12: =IFERROR(IFERROR(E12,0)*IF(B12="GK",2+IFERROR(F12*10,0)+IFERROR(G12*10,0)+IFERROR(H12*10,0)+IFERROR(I12*3,0)-IFERROR(J12*1,0)+IFERROR(K12*4,0)+IFERROR(N12*1,0)+IFERROR(O12*1,0)-IFERROR(L12*2,0)-IFERROR(M12*2,0),IF(B12="DEF",2+IFERROR(F12*6,0)+IFERROR(G12*6,0)+IFERROR(H12*6,0)+IFERROR(I12*3,0)-IFERROR(J12*1,0)+IFERROR(K12*4,0)-IFERROR(L12*2,0)-IFERROR(M12*2,0)+IFERROR(P12*2,0),IF(B12="MID",2+IFERROR(F12*5,0)+IFERROR(G12*5,0)+IFERROR(H12*5,0)+IFERROR(I12*3,0)-IFERROR(J12*1,0)+IFERROR(K12*1,0)+IFERROR(Q12*2,0),IF(B12="FWD",2+IFERROR(F12*4,0)+IFERROR(G12*4,0)+IFERROR(H12*4,0)+IFERROR(I12*3,0)-IFERROR(J12*1,0),"ERROR")))),0) -> 4.7273107 | S12: =MAX(0, MIN(1, -0.021039 + 0.023522 * R12)) -> 0.090156801 | T12: =R12+S12*2 -> 4.9076243 | U12: =VLOOKUP($C12,'Team Fixtures'!$A$2:$Q$21,2,FALSE) -> 0.88924459 | V12: =VLOOKUP($C12,'Team Fixtures'!$A$2:$Q$21,4,FALSE) -> 0.028011204 | W12: =VLOOKUP($C12,'Team Fixtures'!$A$2:$Q$21,5,FALSE) -> 0.86123338 | X12: =VLOOKUP($C12,'Team Fixtures'!$A$2:$Q$21,6,FALSE) -> H | Y12: =R12/(2.926+0.578*U12-0.576*V12-0.561*W12+0.469*IF(X12="H",1,0)) -> 1.3864313 | Z12: =VLOOKUP($C12,'Team Fixtures'!$A$2:$Q$21,2,FALSE) -> 0.88924459 | AA12: =VLOOKUP($C12,'Team Fixtures'!$A$2:$Q$21,8,FALSE) -> 0.89678056 | AB12: =VLOOKUP($C12,'Team Fixtures'!$A$2:$Q$21,9,FALSE) -> -0.0075359711 | AC12: =VLOOKUP($C12,'Team Fixtures'!$A$2:$Q$21,10,FALSE) -> A | AD12: =IFERROR((2.926+0.578*Z12-0.576*AA12-0.561*AB12+0.469*IF(AC12="H",1,0))*$Y12,0) -> 4.059007 | AE12: =MAX(0, MIN(1, -0.021039 + 0.023522 * AD12)) -> 0.074436964 | AF12: =AD12+AE12*2 -> 4.207881 | AG12: =VLOOKUP($C12,'Team Fixtures'!$A$2:$Q$21,2,FALSE) -> 0.88924459 | AH12: =VLOOKUP($C12,'Team Fixtures'!$A$2:$Q$21,12,FALSE) -> 0.10582011 | AI12: =VLOOKUP($C12,'Team Fixtures'!$A$2:$Q$21,13,FALSE) -> 0.78342448 | AJ12: =VLOOKUP($C12,'Team Fixtures'!$A$2:$Q$21,14,FALSE) -> H | AK12: =IFERROR((2.926+0.578*AG12-0.576*AH12-0.561*AI12+0.469*IF(AJ12="H",1,0))*$Y12,0) -> 4.7256925 | AL12: =MAX(0, MIN(1, -0.021039 + 0.023522 * AK12)) -> 0.090118739 | AM12: =AK12+AL12*2 -> 4.90593 | AN12: =VLOOKUP($C12,'Team Fixtures'!$A$2:$Q$21,2,FALSE) -> 0.88924459 | AO12: =VLOOKUP($C12,'Team Fixtures'!$A$2:$Q$21,16,FALSE) -> 0.87939146 | AP12: =VLOOKUP($C12,'Team Fixtures'!$A$2:$Q$21,17,FALSE) -> 0.0098531256 | AQ12: =VLOOKUP($C12,'Team Fixtures'!$A$2:$V$21,18,FALSE) -> H | AR12: =IFERROR((2.926+0.578*AN12-0.576*AO12-0.561*AP12+0.469*IF(AQ12="H",1,0))*$Y12,0) -> 4.709605 | AS12: =MAX(0, MIN(1, -0.021039 + 0.023522 * AR12)) -> 0.089740328 | AT12: =AR12+AS12*2 -> 4.8890856 | AU12: =VLOOKUP($C12,'Team Fixtures'!$A$2:$Q$21,2,FALSE) -> 0.88924459 | AV12: =VLOOKUP($C12,'Team Fixtures'!$A$2:$V$21,20,FALSE) -> 0.50125313 | AW12: =VLOOKUP($C12,'Team Fixtures'!$A$2:$V$21,21,FALSE) -> 0.38799145 | AX12: =VLOOKUP($C12,'Team Fixtures'!$A$2:$V$21,22,FALSE) -> A | AY12: =IFERROR((2.926+0.578*AU12-0.576*AV12-0.561*AW12+0.469*IF(AX12="H",1,0))*$Y12,0) -> 4.0672326 | AZ12: =MAX(0, MIN(1, -0.021039 + 0.023522 * AY12)) -> 0.074630446 | BA12: =AY12+AZ12*2 -> 4.2164935 | BB12: =IFERROR(T12*1+AF12*0.85+AM12*0.7+AT12*0.55+BA12*0.4,0) -> 16.294069
A13: ='Players Full'!CU13 -> Oleksandr Zinchenko | B13: =VLOOKUP(_xlfn.CONCAT('Players Full'!AK13,'Players Full'!BV13),'Players Summarised'!$A$1:$T$1000,20,0) -> DEF | C13: =VLOOKUP('Players Full'!CF13,Teams!$A$1:$G$21,6,0) -> Arsenal | D13: ='Players Full'!BD13/10 -> 5 | E13: =IFERROR(VLOOKUP($A13,'Starting Lineups'!$A$2:$C$510,3,FALSE),0) -> 0 | F13: =VLOOKUP(A13,'Score & Assist'!$A$1:$G$2000,6,0) -> 0.15873016 | G13: =IF(F13<0.3, 0.01,IF(F13=0.3,0.03,IF(F13<0.5,0.05,IF(F13<0.55,0.06,IF(F13<0.57,0.1,IF(F13<0.58,0.11,IF(F13<0.59,0.12,IF(F13<0.6,0.15,0.28)))))))) -> 0.01 | H13: =IF(F13<0.3,0,IF(F13<0.55,0.01,IF(F13<0.59,0.02,IF(F13<0.6,0.03,0.11)))) -> 0 | I13: =VLOOKUP(A13,'Score & Assist'!$A$1:$G$2000,7,0) -> 0.11904762 | J13: =VLOOKUP(A13,'Yellow Card'!$C$1:$E$987,3,0) -> 0.11204482 | K13: =VLOOKUP(C13,'Team Clean Sheet'!$C$2:$F$21,4,0) -> 0.5 | L13: =VLOOKUP(C13,'Team Total Goals'!$D$2:$N$21,10,0) -> 0.17168675 | M13: =VLOOKUP(C13,'Team Total Goals'!$D$2:$N$21,11,0) -> 0.01926849 | N13: =VLOOKUP(A13,'Goalkeeper Saves'!$D$2:$N$15,10,0) -> #N/A | O13: =VLOOKUP(A13,'Goalkeeper Saves'!$D$2:$N$15,11,0) -> #N/A | P13: =IF(B13="DEF",IFERROR(VLOOKUP(A13,'Defensive Contribution - DEF'!A13:H509,8,FALSE),'Defensive Contribution - DEF'!K$2),0) -> 0.2915234 | Q13: =IF(B13="MID",IFERROR(VLOOKUP(A13,'Defensive Contribution - MID'!A$2:I$500,9,FALSE),'Defensive Contribution - MID'!L$2),0) -> 0 | R13: =IFERROR(IFERROR(E13,0)*IF(B13="GK",2+IFERROR(F13*10,0)+IFERROR(G13*10,0)+IFERROR(H13*10,0)+IFERROR(I13*3,0)-IFERROR(J13*1,0)+IFERROR(K13*4,0)+IFERROR(N13*1,0)+IFERROR(O13*1,0)-IFERROR(L13*2,0)-IFERROR(M13*2,0),IF(B13="DEF",2+IFERROR(F13*6,0)+IFERROR(G13*6,0)+IFERROR(H13*6,0)+IFERROR(I13*3,0)-IFERROR(J13*1,0)+IFERROR(K13*4,0)-IFERROR(L13*2,0)-IFERROR(M13*2,0)+IFERROR(P13*2,0),IF(B13="MID",2+IFERROR(F13*5,0)+IFERROR(G13*5,0)+IFERROR(H13*5,0)+IFERROR(I13*3,0)-IFERROR(J13*1,0)+IFERROR(K13*1,0)+IFERROR(Q13*2,0),IF(B13="FWD",2+IFERROR(F13*4,0)+IFERROR(G13*4,0)+IFERROR(H13*4,0)+IFERROR(I13*3,0)-IFERROR(J13*1,0),"ERROR")))),0) -> 0 | S13: =MAX(0, MIN(1, -0.021039 + 0.023522 * R13)) -> 0 | T13: =R13+S13*2 -> 0 | U13: =VLOOKUP($C13,'Team Fixtures'!$A$2:$Q$21,2,FALSE) -> 0.88924459 | V13: =VLOOKUP($C13,'Team Fixtures'!$A$2:$Q$21,4,FALSE) -> 0.028011204 | W13: =VLOOKUP($C13,'Team Fixtures'!$A$2:$Q$21,5,FALSE) -> 0.86123338 | X13: =VLOOKUP($C13,'Team Fixtures'!$A$2:$Q$21,6,FALSE) -> H | Y13: =R13/(2.926+0.578*U13-0.576*V13-0.561*W13+0.469*IF(X13="H",1,0)) -> 0 | Z13: =VLOOKUP($C13,'Team Fixtures'!$A$2:$Q$21,2,FALSE) -> 0.88924459 | AA13: =VLOOKUP($C13,'Team Fixtures'!$A$2:$Q$21,8,FALSE) -> 0.89678056 | AB13: =VLOOKUP($C13,'Team Fixtures'!$A$2:$Q$21,9,FALSE) -> -0.0075359711 | AC13: =VLOOKUP($C13,'Team Fixtures'!$A$2:$Q$21,10,FALSE) -> A | AD13: =IFERROR((2.926+0.578*Z13-0.576*AA13-0.561*AB13+0.469*IF(AC13="H",1,0))*$Y13,0) -> 0 | AE13: =MAX(0, MIN(1, -0.021039 + 0.023522 * AD13)) -> 0 | AF13: =AD13+AE13*2 -> 0 | AG13: =VLOOKUP($C13,'Team Fixtures'!$A$2:$Q$21,2,FALSE) -> 0.88924459 | AH13: =VLOOKUP($C13,'Team Fixtures'!$A$2:$Q$21,12,FALSE) -> 0.10582011 | AI13: =VLOOKUP($C13,'Team Fixtures'!$A$2:$Q$21,13,FALSE) -> 0.78342448 | AJ13: =VLOOKUP($C13,'Team Fixtures'!$A$2:$Q$21,14,FALSE) -> H | AK13: =IFERROR((2.926+0.578*AG13-0.576*AH13-0.561*AI13+0.469*IF(AJ13="H",1,0))*$Y13,0) -> 0 | AL13: =MAX(0, MIN(1, -0.021039 + 0.023522 * AK13)) -> 0 | AM13: =AK13+AL13*2 -> 0 | AN13: =VLOOKUP($C13,'Team Fixtures'!$A$2:$Q$21,2,FALSE) -> 0.88924459 | AO13: =VLOOKUP($C13,'Team Fixtures'!$A$2:$Q$21,16,FALSE) -> 0.87939146 | AP13: =VLOOKUP($C13,'Team Fixtures'!$A$2:$Q$21,17,FALSE) -> 0.0098531256 | AQ13: =VLOOKUP($C13,'Team Fixtures'!$A$2:$V$21,18,FALSE) -> H | AR13: =IFERROR((2.926+0.578*AN13-0.576*AO13-0.561*AP13+0.469*IF(AQ13="H",1,0))*$Y13,0) -> 0 | AS13: =MAX(0, MIN(1, -0.021039 + 0.023522 * AR13)) -> 0 | AT13: =AR13+AS13*2 -> 0 | AU13: =VLOOKUP($C13,'Team Fixtures'!$A$2:$Q$21,2,FALSE) -> 0.88924459 | AV13: =VLOOKUP($C13,'Team Fixtures'!$A$2:$V$21,20,FALSE) -> 0.50125313 | AW13: =VLOOKUP($C13,'Team Fixtures'!$A$2:$V$21,21,FALSE) -> 0.38799145 | AX13: =VLOOKUP($C13,'Team Fixtures'!$A$2:$V$21,22,FALSE) -> A | AY13: =IFERROR((2.926+0.578*AU13-0.576*AV13-0.561*AW13+0.469*IF(AX13="H",1,0))*$Y13,0) -> 0 | AZ13: =MAX(0, MIN(1, -0.021039 + 0.023522 * AY13)) -> 0 | BA13: =AY13+AZ13*2 -> 0 | BB13: =IFERROR(T13*1+AF13*0.85+AM13*0.7+AT13*0.55+BA13*0.4,0) -> 0
... A57: ='Players Full'!CU57 -> John McGinn | B57: =VLOOKUP(_xlfn.CONCAT('Players Full'!AK57,'Players Full'!BV57),'Players Summarised'!$A$1:$T$1000,20,0) -> MID | C57: =VLOOKUP('Players Full'!CF57,Teams!$A$1:$G$21,6,0) -> Aston Villa | D57: ='Players Full'!BD57/10 -> 5.5 | E57: =IFERROR(VLOOKUP($A57,'Starting Lineups'!$A$2:$C$510,3,FALSE),0) -> 1 | F57: =VLOOKUP(A57,'Score & Assist'!$A$1:$G$2000,6,0) -> 0.19047619 | G57: =IF(F57<0.3, 0.01,IF(F57=0.3,0.03,IF(F57<0.5,0.05,IF(F57<0.55,0.06,IF(F57<0.57,0.1,IF(F57<0.58,0.11,IF(F57<0.59,0.12,IF(F57<0.6,0.15,0.28)))))))) -> 0.01 | H57: =IF(F57<0.3,0,IF(F57<0.55,0.01,IF(F57<0.59,0.02,IF(F57<0.6,0.03,0.11)))) -> 0 | I57: =VLOOKUP(A57,'Score & Assist'!$A$1:$G$2000,7,0) -> 0.11904762 | J57: =VLOOKUP(A57,'Yellow Card'!$C$1:$E$987,3,0) -> 0.31746032 | K57: =VLOOKUP(C57,'Team Clean Sheet'!$C$2:$F$21,4,0) -> 0.29039301 | L57: =VLOOKUP(C57,'Team Total Goals'!$D$2:$N$21,10,0) -> 0.3546798 | M57: =VLOOKUP(C57,'Team Total Goals'!$D$2:$N$21,11,0) -> 0.050949051 | N57: =VLOOKUP(A57,'Goalkeeper Saves'!$D$2:$N$15,10,0) -> #N/A | O57: =VLOOKUP(A57,'Goalkeeper Saves'!$D$2:$N$15,11,0) -> #N/A | P57: =IF(B57="DEF",IFERROR(VLOOKUP(A57,'Defensive Contribution - DEF'!A57:H553,8,FALSE),'Defensive Contribution - DEF'!K$2),0) -> 0 | Q57: =IF(B57="MID",IFERROR(VLOOKUP(A57,'Defensive Contribution - MID'!A$2:I$500,9,FALSE),'Defensive Contribution - MID'!L$2),0) -> 0.38575005 | R57: =IFERROR(IFERROR(E57,0)*IF(B57="GK",2+IFERROR(F57*10,0)+IFERROR(G57*10,0)+IFERROR(H57*10,0)+IFERROR(I57*3,0)-IFERROR(J57*1,0)+IFERROR(K57*4,0)+IFERROR(N57*1,0)+IFERROR(O57*1,0)-IFERROR(L57*2,0)-IFERROR(M57*2,0),IF(B57="DEF",2+IFERROR(F57*6,0)+IFERROR(G57*6,0)+IFERROR(H57*6,0)+IFERROR(I57*3,0)-IFERROR(J57*1,0)+IFERROR(K57*4,0)-IFERROR(L57*2,0)-IFERROR(M57*2,0)+IFERROR(P57*2,0),IF(B57="MID",2+IFERROR(F57*5,0)+IFERROR(G57*5,0)+IFERROR(H57*5,0)+IFERROR(I57*3,0)-IFERROR(J57*1,0)+IFERROR(K57*1,0)+IFERROR(Q57*2,0),IF(B57="FWD",2+IFERROR(F57*4,0)+IFERROR(G57*4,0)+IFERROR(H57*4,0)+IFERROR(I57*3,0)-IFERROR(J57*1,0),"ERROR")))),0) -> 4.1039566 | S57: =MAX(0, MIN(1, -0.021039 + 0.023522 * R57)) -> 0.075494267 | T57: =R57+S57*2 -> 4.2549451 | U57: =VLOOKUP($C57,'Team Fixtures'!$A$2:$Q$21,2,FALSE) -> 0.42328042 | V57: =VLOOKUP($C57,'Team Fixtures'!$A$2:$Q$21,4,FALSE) -> 0.056022409 | W57: =VLOOKUP($C57,'Team Fixtures'!$A$2:$Q$21,5,FALSE) -> 0.36725801 | X57: =VLOOKUP($C57,'Team Fixtures'!$A$2:$Q$21,6,FALSE) -> A | Y57: =R57/(2.926+0.578*U57-0.576*V57-0.561*W57+0.469*IF(X57="H",1,0)) -> 1.3995427 | Z57: =VLOOKUP($C57,'Team Fixtures'!$A$2:$Q$21,2,FALSE) -> 0.42328042 | AA57: =VLOOKUP($C57,'Team Fixtures'!$A$2:$Q$21,8,FALSE) -> 0.10582011 | AB57: =VLOOKUP($C57,'Team Fixtures'!$A$2:$Q$21,9,FALSE) -> 0.31746032 | AC57: =VLOOKUP($C57,'Team Fixtures'!$A$2:$Q$21,10,FALSE) -> H | AD57: =IFERROR((2.926+0.578*Z57-0.576*AA57-0.561*AB57+0.469*IF(AC57="H",1,0))*$Y57,0) -> 4.7592967 | AE57: =MAX(0, MIN(1, -0.021039 + 0.023522 * AD57)) -> 0.090909177 | AF57: =AD57+AE57*2 -> 4.9411151 | AG57: =VLOOKUP($C57,'Team Fixtures'!$A$2:$Q$21,2,FALSE) -> 0.42328042 | AH57: =VLOOKUP($C57,'Team Fixtures'!$A$2:$Q$21,12,FALSE) -> 0.086580087 | AI57: =VLOOKUP($C57,'Team Fixtures'!$A$2:$Q$21,13,FALSE) -> 0.33670034 | AJ57: =VLOOKUP($C57,'Team Fixtures'!$A$2:$Q$21,14,FALSE) -> H | AK57: =IFERROR((2.926+0.578*AG57-0.576*AH57-0.561*AI57+0.469*IF(AJ57="H",1,0))*$Y57,0) -> 4.7597006 | AL57: =MAX(0, MIN(1, -0.021039 + 0.023522 * AK57)) -> 0.090918678 | AM57: =AK57+AL57*2 -> 4.941538 | AN57: =VLOOKUP($C57,'Team Fixtures'!$A$2:$Q$21,2,FALSE) -> 0.42328042 | AO57: =VLOOKUP($C57,'Team Fixtures'!$A$2:$Q$21,16,FALSE) -> 0.018674136 | AP57: =VLOOKUP($C57,'Team Fixtures'!$A$2:$Q$21,17,FALSE) -> 0.40460629 | AQ57: =VLOOKUP($C57,'Team Fixtures'!$A$2:$V$21,18,FALSE) -> A | AR57: =IFERROR((2.926+0.578*AN57-0.576*AO57-0.561*AP57+0.469*IF(AQ57="H",1,0))*$Y57,0) -> 4.1047407 | AS57: =MAX(0, MIN(1, -0.021039 + 0.023522 * AR57)) -> 0.07551271 | AT57: =AR57+AS57*2 -> 4.2557661 | AU57: =VLOOKUP($C57,'Team Fixtures'!$A$2:$Q$21,2,FALSE) -> 0.42328042 | AV57: =VLOOKUP($C57,'Team Fixtures'!$A$2:$V$21,20,FALSE) -> 0.063492063 | AW57: =VLOOKUP($C57,'Team Fixtures'!$A$2:$V$21,21,FALSE) -> 0.35978836 | AX57: =VLOOKUP($C57,'Team Fixtures'!$A$2:$V$21,22,FALSE) -> H | AY57: =IFERROR((2.926+0.578*AU57-0.576*AV57-0.561*AW57+0.469*IF(AX57="H",1,0))*$Y57,0) -> 4.7601853 | AZ57: =MAX(0, MIN(1, -0.021039 + 0.023522 * AY57)) -> 0.090930079 | BA57: =AY57+AZ57*2 -> 4.9420455 | BB57: =IFERROR(T57*1+AF57*0.85+AM57*0.7+AT57*0.55+BA57*0.4,0) -> 16.231459
