Workbook

Sheet Data
A1: Team | B1: Gameweek | C1: Opponent | D1: Win | E1: Opponent Win | F1: Diff | G1: Venue | H1: Score 1+ | I1: Assist | J1: Yellow Card | K1: Clean Sheet | L1: Concede 2+ Goals | M1: Concede 4+ Goals | N1: 3+ Saves | O1: 6+ Saves
A2: Arsenal | B2: GW1 | C2: =IF($B2="GW1",VLOOKUP($A2,Matches!$A:$AC,2,FALSE),IF($B2="GW2",VLOOKUP($A2,Matches!$A:$AC,9,FALSE),IF($B2="GW3",VLOOKUP($A2,Matches!$A:$AC,16,FALSE)))) -> Man Utd | D2: 0.49534377 | E2: 0.25482252 | F2: 0.24052125 | G2: A | H2: #N/A | I2: #N/A | J2: 0.21994941 | K2: 0.3373494 | L2: 0.31192661 | M2: 0.042145594 | N2: 0.45351474 | O2: 0
A3: Arsenal | B3: GW1 | C3: =IF($B3="GW1",VLOOKUP($A3,Matches!$A:$AC,2,FALSE),IF($B3="GW2",VLOOKUP($A3,Matches!$A:$AC,9,FALSE),IF($B3="GW3",VLOOKUP($A3,Matches!$A:$AC,16,FALSE)))) -> Man Utd | D3: 0.49534377 | E3: 0.25482252 | F3: 0.24052125 | G3: A | H3: #N/A | I3: #N/A | J3: 0.21994941 | K3: 0.3373494 | L3: 0.31192661 | M3: 0.042145594 | N3: #N/A | O3: #N/A
A4: Arsenal | B4: GW1 | C4: =IF($B4="GW1",VLOOKUP($A4,Matches!$A:$AC,2,FALSE),IF($B4="GW2",VLOOKUP($A4,Matches!$A:$AC,9,FALSE),IF($B4="GW3",VLOOKUP($A4,Matches!$A:$AC,16,FALSE)))) -> Man Utd | D4: 0.49534377 | E4: 0.25482252 | F4: 0.24052125 | G4: A | H4: #N/A | I4: #N/A | J4: #N/A | K4: 0.3373494 | L4: 0.31192661 | M4: 0.042145594 | N4: #N/A | O4: #N/A
A5: Arsenal | B5: GW1 | C5: =IF($B5="GW1",VLOOKUP($A5,Matches!$A:$AC,2,FALSE),IF($B5="GW2",VLOOKUP($A5,Matches!$A:$AC,9,FALSE),IF($B5="GW3",VLOOKUP($A5,Matches!$A:$AC,16,FALSE)))) -> Man Utd | D5: 0.49534377 | E5: 0.25482252 | F5: 0.24052125 | G5: A | H5: #N/A | I5: #N/A | J5: 0.21994941 | K5: 0.3373494 | L5: 0.31192661 | M5: 0.042145594 | N5: #N/A | O5: #N/A
A6: Arsenal | B6: GW1 | C6: =IF($B6="GW1",VLOOKUP($A6,Matches!$A:$AC,2,FALSE),IF($B6="GW2",VLOOKUP($A6,Matches!$A:$AC,9,FALSE),IF($B6="GW3",VLOOKUP($A6,Matches!$A:$AC,16,FALSE)))) -> Man Utd | D6: 0.49534377 | E6: 0.25482252 | F6: 0.24052125 | G6: A | H6: 0.13605442 | I6: 0.041407867 | J6: 0.21994941 | K6: 0.3373494 | L6: 0.31192661 | M6: 0.042145594 | N6: #N/A | O6: #N/A
A7: Arsenal | B7: GW1 | C7: =IF($B7="GW1",VLOOKUP($A7,Matches!$A:$AC,2,FALSE),IF($B7="GW2",VLOOKUP($A7,Matches!$A:$AC,9,FALSE),IF($B7="GW3",VLOOKUP($A7,Matches!$A:$AC,16,FALSE)))) -> Man Utd | D7: 0.49534377 | E7: 0.25482252 | F7: 0.24052125 | G7: A | H7: 0.063492063 | I7: 0.036630037 | J7: 0.19047619 | K7: 0.3373494 | L7: 0.31192661 | M7: 0.042145594 | N7: #N/A | O7: #N/A
A8: Arsenal | B8: GW1 | C8: =IF($B8="GW1",VLOOKUP($A8,Matches!$A:$AC,2,FALSE),IF($B8="GW2",VLOOKUP($A8,Matches!$A:$AC,9,FALSE),IF($B8="GW3",VLOOKUP($A8,Matches!$A:$AC,16,FALSE)))) -> Man Utd | D8: 0.49534377 | E8: 0.25482252 | F8: 0.24052125 | G8: A | H8: 0.079365079 | I8: 0.086580087 | J8: 0.28011204 | K8: 0.3373494 | L8: 0.31192661 | M8: 0.042145594 | N8: #N/A | O8: #N/A
A9: Arsenal | B9: GW1 | C9: =IF($B9="GW1",VLOOKUP($A9,Matches!$A:$AC,2,FALSE),IF($B9="GW2",VLOOKUP($A9,Matches!$A:$AC,9,FALSE),IF($B9="GW3",VLOOKUP($A9,Matches!$A:$AC,16,FALSE)))) -> Man Utd | D9: 0.49534377 | E9: 0.25482252 | F9: 0.24052125 | G9: A | H9: #N/A | I9: #N/A | J9: #N/A | K9: 0.3373494 | L9: 0.31192661 | M9: 0.042145594 | N9: #N/A | O9: #N/A
A10: Arsenal | B10: GW1 | C10: =IF($B10="GW1",VLOOKUP($A10,Matches!$A:$AC,2,FALSE),IF($B10="GW2",VLOOKUP($A10,Matches!$A:$AC,9,FALSE),IF($B10="GW3",VLOOKUP($A10,Matches!$A:$AC,16,FALSE)))) -> Man Utd | D10: 0.49534377 | E10: 0.25482252 | F10: 0.24052125 | G10: A | H10: 0.063492063 | I10: 0.073260073 | J10: 0.21994941 | K10: 0.3373494 | L10: 0.31192661 | M10: 0.042145594 | N10: #N/A | O10: #N/A
A11: Arsenal | B11: GW1 | C11: =IF($B11="GW1",VLOOKUP($A11,Matches!$A:$AC,2,FALSE),IF($B11="GW2",VLOOKUP($A11,Matches!$A:$AC,9,FALSE),IF($B11="GW3",VLOOKUP($A11,Matches!$A:$AC,16,FALSE)))) -> Man Utd | D11: 0.49534377 | E11: 0.25482252 | F11: 0.24052125 | G11: A | H11: 0.10025063 | I11: 0.063492063 | J11: 0.28011204 | K11: 0.3373494 | L11: 0.31192661 | M11: 0.042145594 | N11: #N/A | O11: #N/A
A12: Arsenal | B12: GW1 | C12: =IF($B12="GW1",VLOOKUP($A12,Matches!$A:$AC,2,FALSE),IF($B12="GW2",VLOOKUP($A12,Matches!$A:$AC,9,FALSE),IF($B12="GW3",VLOOKUP($A12,Matches!$A:$AC,16,FALSE)))) -> Man Utd | D12: 0.49534377 | E12: 0.25482252 | F12: 0.24052125 | G12: A | H12: 0.063492063 | I12: 0.086580087 | J12: 0.25396825 | K12: 0.3373494 | L12: 0.31192661 | M12: 0.042145594 | N12: #N/A | O12: #N/A
A13: Arsenal | B13: GW1 | C13: =IF($B13="GW1",VLOOKUP($A13,Matches!$A:$AC,2,FALSE),IF($B13="GW2",VLOOKUP($A13,Matches!$A:$AC,9,FALSE),IF($B13="GW3",VLOOKUP($A13,Matches!$A:$AC,16,FALSE)))) -> Man Utd | D13: 0.49534377 | E13: 0.25482252 | F13: 0.24052125 | G13: A | H13: 0.11904762 | I13: 0.086580087 | J13: 0.19047619 | K13: 0.3373494 | L13: 0.31192661 | M13: 0.042145594 | N13: #N/A | O13: #N/A
A14: Arsenal | B14: GW1 | C14: =IF($B14="GW1",VLOOKUP($A14,Matches!$A:$AC,2,FALSE),IF($B14="GW2",VLOOKUP($A14,Matches!$A:$AC,9,FALSE),IF($B14="GW3",VLOOKUP($A14,Matches!$A:$AC,16,FALSE)))) -> Man Utd | D14: 0.49534377 | E14: 0.25482252 | F14: 0.24052125 | G14: A | H14: #N/A | I14: #N/A | J14: #N/A | K14: 0.3373494 | L14: 0.31192661 | M14: 0.042145594 | N14: #N/A | O14: #N/A
A15: Arsenal | B15: GW1 | C15: =IF($B15="GW1",VLOOKUP($A15,Matches!$A:$AC,2,FALSE),IF($B15="GW2",VLOOKUP($A15,Matches!$A:$AC,9,FALSE),IF($B15="GW3",VLOOKUP($A15,Matches!$A:$AC,16,FALSE)))) -> Man Utd | D15: 0.49534377 | E15: 0.25482252 | F15: 0.24052125 | G15: A | H15: #N/A | I15: #N/A | J15: #N/A | K15: 0.3373494 | L15: 0.31192661 | M15: 0.042145594 | N15: #N/A | O15: #N/A
A16: Arsenal | B16: GW1 | C16: =IF($B16="GW1",VLOOKUP($A16,Matches!$A:$AC,2,FALSE),IF($B16="GW2",VLOOKUP($A16,Matches!$A:$AC,9,FALSE),IF($B16="GW3",VLOOKUP($A16,Matches!$A:$AC,16,FALSE)))) -> Man Utd | D16: 0.49534377 | E16: 0.25482252 | F16: 0.24052125 | G16: A | H16: #N/A | I16: #N/A | J16: #N/A | K16: 0.3373494 | L16: 0.31192661 | M16: 0.042145594 | N16: #N/A | O16: #N/A
A17: Arsenal | B17: GW1 | C17: =IF($B17="GW1",VLOOKUP($A17,Matches!$A:$AC,2,FALSE),IF($B17="GW2",VLOOKUP($A17,Matches!$A:$AC,9,FALSE),IF($B17="GW3",VLOOKUP($A17,Matches!$A:$AC,16,FALSE)))) -> Man Utd | D17: 0.49534377 | E17: 0.25482252 | F17: 0.24052125 | G17: A | H17: 0.33184005 | I17: 0.25396825 | J17: 0.20050125 | K17: 0.3373494 | L17: 0.31192661 | M17: 0.042145594 | N17: #N/A | O17: #N/A
A18: Arsenal | B18: GW1 | C18: =IF($B18="GW1",VLOOKUP($A18,Matches!$A:$AC,2,FALSE),IF($B18="GW2",VLOOKUP($A18,Matches!$A:$AC,9,FALSE),IF($B18="GW3",VLOOKUP($A18,Matches!$A:$AC,16,FALSE)))) -> Man Utd | D18: 0.49534377 | E18: 0.25482252 | F18: 0.24052125 | G18: A | H18: 0.25396825 | I18: 0.21164021 | J18: 0.17316017 | K18: 0.3373494 | L18: 0.31192661 | M18: 0.042145594 | N18: #N/A | O18: #N/A
A19: Arsenal | B19: GW1 | C19: =IF($B19="GW1",VLOOKUP($A19,Matches!$A:$AC,2,FALSE),IF($B19="GW2",VLOOKUP($A19,Matches!$A:$AC,9,FALSE),IF($B19="GW3",VLOOKUP($A19,Matches!$A:$AC,16,FALSE)))) -> Man Utd | D19: 0.49534377 | E19: 0.25482252 | F19: 0.24052125 | G19: A | H19: 0.28011204 | I19: 0.17316017 | J19: 0.11904762 | K19: 0.3373494 | L19: 0.31192661 | M19: 0.042145594 | N19: #N/A | O19: #N/A
A20: Arsenal | B20: GW1 | C20: =IF($B20="GW1",VLOOKUP($A20,Matches!$A:$AC,2,FALSE),IF($B20="GW2",VLOOKUP($A20,Matches!$A:$AC,9,FALSE),IF($B20="GW3",VLOOKUP($A20,Matches!$A:$AC,16,FALSE)))) -> Man Utd | D20: 0.49534377 | E20: 0.25482252 | F20: 0.24052125 | G20: A | H20: 0.28011204 | I20: 0.19047619 | J20: 0.15873016 | K20: 0.3373494 | L20: 0.31192661 | M20: 0.042145594 | N20: #N/A | O20: #N/A
A21: Arsenal | B21: GW1 | C21: =IF($B21="GW1",VLOOKUP($A21,Matches!$A:$AC,2,FALSE),IF($B21="GW2",VLOOKUP($A21,Matches!$A:$AC,9,FALSE),IF($B21="GW3",VLOOKUP($A21,Matches!$A:$AC,16,FALSE)))) -> Man Utd | D21: 0.49534377 | E21: 0.25482252 | F21: 0.24052125 | G21: A | H21: 0.31746032 | I21: 0.17316017 | J21: 0.13605442 | K21: 0.3373494 | L21: 0.31192661 | M21: 0.042145594 | N21: #N/A | O21: #N/A
A22: Arsenal | B22: GW1 | C22: =IF($B22="GW1",VLOOKUP($A22,Matches!$A:$AC,2,FALSE),IF($B22="GW2",VLOOKUP($A22,Matches!$A:$AC,9,FALSE),IF($B22="GW3",VLOOKUP($A22,Matches!$A:$AC,16,FALSE)))) -> Man Utd | D22: 0.49534377 | E22: 0.25482252 | F22: 0.24052125 | G22: A | H22: 0.17316017 | I22: 0.17316017 | J22: 0.21994941 | K22: 0.3373494 | L22: 0.31192661 | M22: 0.042145594 | N22: #N/A | O22: #N/A
A23: Arsenal | B23: GW1 | C23: =IF($B23="GW1",VLOOKUP($A23,Matches!$A:$AC,2,FALSE),IF($B23="GW2",VLOOKUP($A23,Matches!$A:$AC,9,FALSE),IF($B23="GW3",VLOOKUP($A23,Matches!$A:$AC,16,FALSE)))) -> Man Utd | D23: 0.49534377 | E23: 0.25482252 | F23: 0.24052125 | G23: A | H23: #N/A | I23: #N/A | J23: #N/A | K23: 0.3373494 | L23: 0.31192661 | M23: 0.042145594 | N23: #N/A | O23: #N/A
A24: Arsenal | B24: GW1 | C24: =IF($B24="GW1",VLOOKUP($A24,Matches!$A:$AC,2,FALSE),IF($B24="GW2",VLOOKUP($A24,Matches!$A:$AC,9,FALSE),IF($B24="GW3",VLOOKUP($A24,Matches!$A:$AC,16,FALSE)))) -> Man Utd | D24: 0.49534377 | E24: 0.25482252 | F24: 0.24052125 | G24: A | H24: #N/A | I24: #N/A | J24: #N/A | K24: 0.3373494 | L24: 0.31192661 | M24: 0.042145594 | N24: #N/A | O24: #N/A
A25: Arsenal | B25: GW1 | C25: =IF($B25="GW1",VLOOKUP($A25,Matches!$A:$AC,2,FALSE),IF($B25="GW2",VLOOKUP($A25,Matches!$A:$AC,9,FALSE),IF($B25="GW3",VLOOKUP($A25,Matches!$A:$AC,16,FALSE)))) -> Man Utd | D25: 0.49534377 | E25: 0.25482252 | F25: 0.24052125 | G25: A | H25: 0.11204482 | I25: 0.073260073 | J25: 0.33184005 | K25: 0.3373494 | L25: 0.31192661 | M25: 0.042145594 | N25: #N/A | O25: #N/A
A26: Arsenal | B26: GW1 | C26: =IF($B26="GW1",VLOOKUP($A26,Matches!$A:$AC,2,FALSE),IF($B26="GW2",VLOOKUP($A26,Matches!$A:$AC,9,FALSE),IF($B26="GW3",VLOOKUP($A26,Matches!$A:$AC,16,FALSE)))) -> Man Utd | D26: 0.49534377 | E26: 0.25482252 | F26: 0.24052125 | G26: A | H26: 0.31746032 | I26: 0.15873016 | J26: 0.17316017 | K26: 0.3373494 | L26: 0.31192661 | M26: 0.042145594 | N26: #N/A | O26: #N/A
A27: Arsenal | B27: GW1 | C27: =IF($B27="GW1",VLOOKUP($A27,Matches!$A:$AC,2,FALSE),IF($B27="GW2",VLOOKUP($A27,Matches!$A:$AC,9,FALSE),IF($B27="GW3",VLOOKUP($A27,Matches!$A:$AC,16,FALSE)))) -> Man Utd | D27: 0.49534377 | E27: 0.25482252 | F27: 0.24052125 | G27: A | H27: 0.14652015 | I27: 0.11904762 | J27: 0.20050125 | K27: 0.3373494 | L27: 0.31192661 | M27: 0.042145594 | N27: #N/A | O27: #N/A
A28: Arsenal | B28: GW1 | C28: =IF($B28="GW1",VLOOKUP($A28,Matches!$A:$AC,2,FALSE),IF($B28="GW2",VLOOKUP($A28,Matches!$A:$AC,9,FALSE),IF($B28="GW3",VLOOKUP($A28,Matches!$A:$AC,16,FALSE)))) -> Man Utd | D28: 0.49534377 | E28: 0.25482252 | F28: 0.24052125 | G28: A | H28: 0.25396825 | I28: 0.17316017 | J28: 0.25396825 | K28: 0.3373494 | L28: 0.31192661 | M28: 0.042145594 | N28: #N/A | O28: #N/A
A29: Arsenal | B29: GW1 | C29: =IF($B29="GW1",VLOOKUP($A29,Matches!$A:$AC,2,FALSE),IF($B29="GW2",VLOOKUP($A29,Matches!$A:$AC,9,FALSE),IF($B29="GW3",VLOOKUP($A29,Matches!$A:$AC,16,FALSE)))) -> Man Utd | D29: 0.49534377 | E29: 0.25482252 | F29: 0.24052125 | G29: A | H29: #N/A | I29: #N/A | J29: #N/A | K29: 0.3373494 | L29: 0.31192661 | M29: 0.042145594 | N29: #N/A | O29: #N/A
A30: Arsenal | B30: GW1 | C30: =IF($B30="GW1",VLOOKUP($A30,Matches!$A:$AC,2,FALSE),IF($B30="GW2",VLOOKUP($A30,Matches!$A:$AC,9,FALSE),IF($B30="GW3",VLOOKUP($A30,Matches!$A:$AC,16,FALSE)))) -> Man Utd | D30: 0.49534377 | E30: 0.25482252 | F30: 0.24052125 | G30: A | H30: 0.14652015 | I30: 0.10582011 | J30: 0.28011204 | K30: 0.3373494 | L30: 0.31192661 | M30: 0.042145594 | N30: #N/A | O30: #N/A
A31: Arsenal | B31: GW1 | C31: =IF($B31="GW1",VLOOKUP($A31,Matches!$A:$AC,2,FALSE),IF($B31="GW2",VLOOKUP($A31,Matches!$A:$AC,9,FALSE),IF($B31="GW3",VLOOKUP($A31,Matches!$A:$AC,16,FALSE)))) -> Man Utd | D31: 0.49534377 | E31: 0.25482252 | F31: 0.24052125 | G31: A | H31: 0.31746032 | I31: 0.095238095 | J31: 0.28011204 | K31: 0.3373494 | L31: 0.31192661 | M31: 0.042145594 | N31: #N/A | O31: #N/A
A32: Arsenal | B32: GW1 | C32: =IF($B32="GW1",VLOOKUP($A32,Matches!$A:$AC,2,FALSE),IF($B32="GW2",VLOOKUP($A32,Matches!$A:$AC,9,FALSE),IF($B32="GW3",VLOOKUP($A32,Matches!$A:$AC,16,FALSE)))) -> Man Utd | D32: 0.49534377 | E32: 0.25482252 | F32: 0.24052125 | G32: A | H32: #N/A | I32: #N/A | J32: #N/A | K32: 0.3373494 | L32: 0.31192661 | M32: 0.042145594 | N32: #N/A | O32: #N/A
A33: Arsenal | B33: GW1 | C33: =IF($B33="GW1",VLOOKUP($A33,Matches!$A:$AC,2,FALSE),IF($B33="GW2",VLOOKUP($A33,Matches!$A:$AC,9,FALSE),IF($B33="GW3",VLOOKUP($A33,Matches!$A:$AC,16,FALSE)))) -> Man Utd | D33: 0.49534377 | E33: 0.25482252 | F33: 0.24052125 | G33: A | H33: 0.079365079 | I33: 0.045351474 | J33: 0.19047619 | K33: 0.3373494 | L33: 0.31192661 | M33: 0.042145594 | N33: #N/A | O33: #N/A
A34: Arsenal | B34: GW1 | C34: =IF($B34="GW1",VLOOKUP($A34,Matches!$A:$AC,2,FALSE),IF($B34="GW2",VLOOKUP($A34,Matches!$A:$AC,9,FALSE),IF($B34="GW3",VLOOKUP($A34,Matches!$A:$AC,16,FALSE)))) -> Man Utd | D34: 0.49534377 | E34: 0.25482252 | F34: 0.24052125 | G34: A | H34: 0.48840049 | I34: 0.14652015 | J34: 0.19047619 | K34: 0.3373494 | L34: 0.31192661 | M34: 0.042145594 | N34: #N/A | O34: #N/A
A35: Aston Villa | B35: GW1 | C35: =IF($B35="GW1",VLOOKUP($A35,Matches!$A:$AC,2,FALSE),IF($B35="GW2",VLOOKUP($A35,Matches!$A:$AC,9,FALSE),IF($B35="GW3",VLOOKUP($A35,Matches!$A:$AC,16,FALSE)))) -> Newcastle | D35: 0.40453074 | E35: 0.3279979 | F35: 0.076532844 | G35: H | H35: #N/A | I35: #N/A | J35: 0.14652015 | K35: 0.25 | L35: 0.42257218 | M35: 0.064254523 | N35: 0.47619048 | O35: 0
A36: Aston Villa | B36: GW1 | C36: =IF($B36="GW1",VLOOKUP($A36,Matches!$A:$AC,2,FALSE),IF($B36="GW2",VLOOKUP($A36,Matches!$A:$AC,9,FALSE),IF($B36="GW3",VLOOKUP($A36,Matches!$A:$AC,16,FALSE)))) -> Newcastle | D36: 0.40453074 | E36: 0.3279979 | F36: 0.076532844 | G36: H | H36: #N/A | I36: #N/A | J36: 0.079365079 | K36: 0.25 | L36: 0.42257218 | M36: 0.064254523 | N36: #N/A | O36: #N/A
A37: Aston Villa | B37: GW1 | C37: =IF($B37="GW1",VLOOKUP($A37,Matches!$A:$AC,2,FALSE),IF($B37="GW2",VLOOKUP($A37,Matches!$A:$AC,9,FALSE),IF($B37="GW3",VLOOKUP($A37,Matches!$A:$AC,16,FALSE)))) -> Newcastle | D37: 0.40453074 | E37: 0.3279979 | F37: 0.076532844 | G37: H | H37: #N/A | I37: #N/A | J37: 0.11204482 | K37: 0.25 | L37: 0.42257218 | M37: 0.064254523 | N37: #N/A | O37: #N/A
A38: Aston Villa | B38: GW1 | C38: =IF($B38="GW1",VLOOKUP($A38,Matches!$A:$AC,2,FALSE),IF($B38="GW2",VLOOKUP($A38,Matches!$A:$AC,9,FALSE),IF($B38="GW3",VLOOKUP($A38,Matches!$A:$AC,16,FALSE)))) -> Newcastle | D38: 0.40453074 | E38: 0.3279979 | F38: 0.076532844 | G38: H | H38: #N/A | I38: #N/A | J38: #N/A | K38: 0.25 | L38: 0.42257218 | M38: 0.064254523 | N38: #N/A | O38: #N/A
A39: Aston Villa | B39: GW1 | C39: =IF($B39="GW1",VLOOKUP($A39,Matches!$A:$AC,2,FALSE),IF($B39="GW2",VLOOKUP($A39,Matches!$A:$AC,9,FALSE),IF($B39="GW3",VLOOKUP($A39,Matches!$A:$AC,16,FALSE)))) -> Newcastle | D39: 0.40453074 | E39: 0.3279979 | F39: 0.076532844 | G39: H | H39: 0.14652015 | I39: 0.086580087 | J39: 0.27210884 | K39: 0.25 | L39: 0.42257218 | M39: 0.064254523 | N39: #N/A | O39: #N/A
A40: Aston Villa | B40: GW1 | C40: =IF($B40="GW1",VLOOKUP($A40,Matches!$A:$AC,2,FALSE),IF($B40="GW2",VLOOKUP($A40,Matches!$A:$AC,9,FALSE),IF($B40="GW3",VLOOKUP($A40,Matches!$A:$AC,16,FALSE)))) -> Newcastle | D40: 0.40453074 | E40: 0.3279979 | F40: 0.076532844 | G40: H | H40: 0.086580087 | I40: 0.15873016 | J40: 0.27210884 | K40: 0.25 | L40: 0.42257218 | M40: 0.064254523 | N40: #N/A | O40: #N/A
...

Sheet Matches
A1: Team | B1: GW1 Opponent | C1: GW1 Winner Prob | D1: GW1 Relegation Prob | E1: GW1 Opponent Winner Prob | F1: GW1 Opponent Relegation Prob | G1: GW1 Venue | H1: GW1 Match Win Prob | I1: GW2 Opponent | J1: GW2 Winner Prob | K1: GW2 Relegation Prob | L1: GW2 Opponent Winner Prob | M1: GW2 Opponent Relegation Prob | N1: GW2 Venue | O1: GW2 Match Win Prob | P1: GW3 Opponent | Q1: GW3 Winner Prob | R1: GW3 Relegation Prob | S1: GW3 Opponent Winner Prob | T1: GW3 Opponent Relegation Prob | U1: GW3 Venue | V1: GW3 Match Win Prob | W1: GW4 Opponent | X1: GW4 Winner Prob | Y1: GW4 Relegation Prob | Z1: GW4 Opponent Winner Prob | AA1: GW4 Opponent Relegation Prob | AB1: GW4 Venue | AC1: GW4 Match Win Prob
A2: Arsenal | B2: Man Utd | C2: =VLOOKUP($A2,'[1]Outright Odds GW1'!$A:$C,2,FALSE) -> 0.26092629 | D2: =VLOOKUP($A2,'[1]Outright Odds GW1'!$A:$C,3,FALSE) -> 0.00095142952 | E2: =VLOOKUP(B2,'[1]Outright Odds GW1'!$A:$C,2,FALSE) -> 0.036630037 | F2: =VLOOKUP(B2,'[1]Outright Odds GW1'!$A:$C,3,FALSE) -> 0.018674136 | G2: A | H2: =1/1.96/1.03 -> 0.49534377 | I2: Leeds | J2: =VLOOKUP($A2,'[1]Outright Odds GW2'!$A:$C,2,FALSE) -> 0.26092629 | K2: =VLOOKUP($A2,'[1]Outright Odds GW2'!$A:$C,3,FALSE) -> 0.00095142952 | L2: =VLOOKUP(I2,'[1]Outright Odds GW2'!$A:$C,2,FALSE) -> 0.00095142952 | M2: =VLOOKUP(I2,'[1]Outright Odds GW2'!$A:$C,3,FALSE) -> 0.3968254 | N2: H | O2: =1/1.34/1.03 -> 0.72453268 | P2: Liverpool | Q2: =VLOOKUP($A2,'[1]Outright Odds GW3'!$A:$C,2,FALSE) -> 0.34632035 | R2: =VLOOKUP($A2,'[1]Outright Odds GW3'!$A:$C,3,FALSE) -> 0.00095142952 | S2: =VLOOKUP(P2,'[1]Outright Odds GW3'!$A:$C,2,FALSE) -> 0.34632035 | T2: =VLOOKUP(P2,'[1]Outright Odds GW3'!$A:$C,3,FALSE) -> 0.00063449764 | U2: A | V2: =1/3.67/1.03 -> 0.26454327 | W2: Nott'm Forest | X2: =VLOOKUP($A2,'[1]Outright Odds GW4'!$A:$C,2,FALSE) -> 0.34632035 | Y2: =VLOOKUP($A2,'[1]Outright Odds GW4'!$A:$C,3,FALSE) -> 0.00095142952 | Z2: =VLOOKUP(W2,'[1]Outright Odds GW4'!$A:$C,2,FALSE) -> 0.0063071586 | AA2: =VLOOKUP(W2,'[1]Outright Odds GW4'!$A:$C,3,FALSE) -> 0.086580087 | AB2: H | AC2: =1/1.42/1.03 -> 0.68371393
A3: Aston Villa | B3: Newcastle | C3: =VLOOKUP($A3,'[1]Outright Odds GW1'!$A:$C,2,FALSE) -> 0.0094295144 | D3: =VLOOKUP($A3,'[1]Outright Odds GW1'!$A:$C,3,FALSE) -> 0.0063071586 | E3: =VLOOKUP(B3,'[1]Outright Odds GW1'!$A:$C,2,FALSE) -> 0.013413816 | F3: =VLOOKUP(B3,'[1]Outright Odds GW1'!$A:$C,3,FALSE) -> 0.0047382137 | G3: H | H3: =1/2.4/1.03 -> 0.40453074 | I3: Brentford | J3: =VLOOKUP($A3,'[1]Outright Odds GW2'!$A:$C,2,FALSE) -> 0.0094295144 | K3: =VLOOKUP($A3,'[1]Outright Odds GW2'!$A:$C,3,FALSE) -> 0.0063071586 | L3: =VLOOKUP(I3,'[1]Outright Odds GW2'!$A:$C,2,FALSE) -> 0.00095142952 | M3: =VLOOKUP(I3,'[1]Outright Odds GW2'!$A:$C,3,FALSE) -> 0.23809524 | N3: A | O3: =1/2.15/1.03 -> 0.4515692 | P3: Crystal Palace | Q3: =VLOOKUP($A3,'[1]Outright Odds GW3'!$A:$C,2,FALSE) -> 0.0063071586 | R3: =VLOOKUP($A3,'[1]Outright Odds GW3'!$A:$C,3,FALSE) -> 0.018674136 | S3: =VLOOKUP(P3,'[1]Outright Odds GW3'!$A:$C,2,FALSE) -> 0.00190096 | T3: =VLOOKUP(P3,'[1]Outright Odds GW3'!$A:$C,3,FALSE) -> 0.095238095 | U3: H | V3: =1/1.85/1.03 -> 0.52479664 | W3: Everton | X3: =VLOOKUP($A3,'[1]Outright Odds GW4'!$A:$C,2,FALSE) -> 0.0063071586 | Y3: =VLOOKUP($A3,'[1]Outright Odds GW4'!$A:$C,3,FALSE) -> 0.018674136 | Z3: =VLOOKUP(W3,'[1]Outright Odds GW4'!$A:$C,2,FALSE) -> 0.00190096 | AA3: =VLOOKUP(W3,'[1]Outright Odds GW4'!$A:$C,3,FALSE) -> 0.095238095 | AB3: A | AC3: =1/2.36/1.03 -> 0.4113872
A4: Bournemouth | B4: Liverpool | C4: =VLOOKUP($A4,'[1]Outright Odds GW1'!$A:$C,2,FALSE) -> 0.0012681504 | D4: =VLOOKUP($A4,'[1]Outright Odds GW1'!$A:$C,3,FALSE) -> 0.079365079 | E4: =VLOOKUP(B4,'[1]Outright Odds GW1'!$A:$C,2,FALSE) -> 0.32840722 | F4: =VLOOKUP(B4,'[1]Outright Odds GW1'!$A:$C,3,FALSE) -> 0.00095142952 | G4: A | H4: =1/8.97/1.03 -> 0.10823565 | I4: Wolves | J4: =VLOOKUP($A4,'[1]Outright Odds GW2'!$A:$C,2,FALSE) -> 0.0012681504 | K4: =VLOOKUP($A4,'[1]Outright Odds GW2'!$A:$C,3,FALSE) -> 0.079365079 | L4: =VLOOKUP(I4,'[1]Outright Odds GW2'!$A:$C,2,FALSE) -> 0.00095142952 | M4: =VLOOKUP(I4,'[1]Outright Odds GW2'!$A:$C,3,FALSE) -> 0.21978022 | N4: H | O4: =1/1.81/1.03 -> 0.53639436 | P4: Spurs | Q4: =VLOOKUP($A4,'[1]Outright Odds GW3'!$A:$C,2,FALSE) -> 0.00190096 | R4: =VLOOKUP($A4,'[1]Outright Odds GW3'!$A:$C,3,FALSE) -> 0.086580087 | S4: =VLOOKUP(P4,'[1]Outright Odds GW3'!$A:$C,2,FALSE) -> 0.036630037 | T4: =VLOOKUP(P4,'[1]Outright Odds GW3'!$A:$C,3,FALSE) -> 0.0063071586 | U4: A | V4: =1/4.61/1.03 -> 0.21060169 | W4: Brighton | X4: =VLOOKUP($A4,'[1]Outright Odds GW4'!$A:$C,2,FALSE) -> 0.00190096 | Y4: =VLOOKUP($A4,'[1]Outright Odds GW4'!$A:$C,3,FALSE) -> 0.086580087 | Z4: =VLOOKUP(W4,'[1]Outright Odds GW4'!$A:$C,2,FALSE) -> 0.00190096 | AA4: =VLOOKUP(W4,'[1]Outright Odds GW4'!$A:$C,3,FALSE) -> 0.056022409 | AB4: H | AC4: =1/2.4/1.03 -> 0.40453074
A5: Brentford | B5: Nott'm Forest | C5: =VLOOKUP($A5,'[1]Outright Odds GW1'!$A:$C,2,FALSE) -> 0.00095142952 | D5: =VLOOKUP($A5,'[1]Outright Odds GW1'!$A:$C,3,FALSE) -> 0.23809524 | E5: =VLOOKUP(B5,'[1]Outright Odds GW1'!$A:$C,2,FALSE) -> 0.00190096 | F5: =VLOOKUP(B5,'[1]Outright Odds GW1'!$A:$C,3,FALSE) -> 0.086580087 | G5: A | H5: =1/4.24/1.03 -> 0.22897967 | I5: Aston Villa | J5: =VLOOKUP($A5,'[1]Outright Odds GW2'!$A:$C,2,FALSE) -> 0.00095142952 | K5: =VLOOKUP($A5,'[1]Outright Odds GW2'!$A:$C,3,FALSE) -> 0.23809524 | L5: =VLOOKUP(I5,'[1]Outright Odds GW2'!$A:$C,2,FALSE) -> 0.0094295144 | M5: =VLOOKUP(I5,'[1]Outright Odds GW2'!$A:$C,3,FALSE) -> 0.0063071586 | N5: H | O5: =1/3.4/1.03 -> 0.28555111 | P5: Sunderland | Q5: =VLOOKUP($A5,'[1]Outright Odds GW3'!$A:$C,2,FALSE) -> 0.00095142952 | R5: =VLOOKUP($A5,'[1]Outright Odds GW3'!$A:$C,3,FALSE) -> 0.25396825 | S5: =VLOOKUP(P5,'[1]Outright Odds GW3'!$A:$C,2,FALSE) -> 0.00063449764 | T5: =VLOOKUP(P5,'[1]Outright Odds GW3'!$A:$C,3,FALSE) -> 0.60661207 | U5: A | V5: =1/2.63/1.03 -> 0.36915353 | W5: Chelsea | X5: =VLOOKUP($A5,'[1]Outright Odds GW4'!$A:$C,2,FALSE) -> 0.00095142952 | Y5: =VLOOKUP($A5,'[1]Outright Odds GW4'!$A:$C,3,FALSE) -> 0.25396825 | Z5: =VLOOKUP(W5,'[1]Outright Odds GW4'!$A:$C,2,FALSE) -> 0.11904762 | AA5: =VLOOKUP(W5,'[1]Outright Odds GW4'!$A:$C,3,FALSE) -> 0.00190096 | AB5: H | AC5: =1/4.6/1.03 -> 0.21105952
A6: Brighton | B6: Fulham | C6: =VLOOKUP($A6,'[1]Outright Odds GW1'!$A:$C,2,FALSE) -> 0.0037943464 | D6: =VLOOKUP($A6,'[1]Outright Odds GW1'!$A:$C,3,FALSE) -> 0.041407867 | E6: =VLOOKUP(B6,'[1]Outright Odds GW1'!$A:$C,2,FALSE) -> 0.00095142952 | F6: =VLOOKUP(B6,'[1]Outright Odds GW1'!$A:$C,3,FALSE) -> 0.073260073 | G6: H | H6: =1/1.84/1.03 -> 0.5276488 | I6: Everton | J6: =VLOOKUP($A6,'[1]Outright Odds GW2'!$A:$C,2,FALSE) -> 0.0037943464 | K6: =VLOOKUP($A6,'[1]Outright Odds GW2'!$A:$C,3,FALSE) -> 0.041407867 | L6: =VLOOKUP(I6,'[1]Outright Odds GW2'!$A:$C,2,FALSE) -> 0.00190096 | M6: =VLOOKUP(I6,'[1]Outright Odds GW2'!$A:$C,3,FALSE) -> 0.10025063 | N6: A | O6: =1/2.43/1.03 -> 0.39953654 | P6: Man City | Q6: =VLOOKUP($A6,'[1]Outright Odds GW3'!$A:$C,2,FALSE) -> 0.00190096 | R6: =VLOOKUP($A6,'[1]Outright Odds GW3'!$A:$C,3,FALSE) -> 0.056022409 | S6: =VLOOKUP(P6,'[1]Outright Odds GW3'!$A:$C,2,FALSE) -> 0.17316017 | T6: =VLOOKUP(P6,'[1]Outright Odds GW3'!$A:$C,3,FALSE) -> 0.045351474 | U6: H | V6: =1/4.28/1.03 -> 0.22683967 | W6: Bournemouth | X6: =VLOOKUP($A6,'[1]Outright Odds GW4'!$A:$C,2,FALSE) -> 0.00190096 | Y6: =VLOOKUP($A6,'[1]Outright Odds GW4'!$A:$C,3,FALSE) -> 0.056022409 | Z6: =VLOOKUP(W6,'[1]Outright Odds GW4'!$A:$C,2,FALSE) -> 0.00190096 | AA6: =VLOOKUP(W6,'[1]Outright Odds GW4'!$A:$C,3,FALSE) -> 0.086580087 | AB6: A | AC6: =1/2.81/1.03 -> 0.34550669
A7: Burnley | B7: Spurs | C7: =VLOOKUP($A7,'[1]Outright Odds GW1'!$A:$C,2,FALSE) -> 0.0004759525 | D7: =VLOOKUP($A7,'[1]Outright Odds GW1'!$A:$C,3,FALSE) -> 0.68027211 | E7: =VLOOKUP(B7,'[1]Outright Odds GW1'!$A:$C,2,FALSE) -> 0.018674136 | F7: =VLOOKUP(B7,'[1]Outright Odds GW1'!$A:$C,3,FALSE) -> 0.0094295144 | G7: A | H7: =1/6.39/1.03 -> 0.15193643 | I7: Sunderland | J7: =VLOOKUP($A7,'[1]Outright Odds GW2'!$A:$C,2,FALSE) -> 0.0004759525 | K7: =VLOOKUP($A7,'[1]Outright Odds GW2'!$A:$C,3,FALSE) -> 0.68027211 | L7: =VLOOKUP(I7,'[1]Outright Odds GW2'!$A:$C,2,FALSE) -> 0.0004759525 | M7: =VLOOKUP(I7,'[1]Outright Odds GW2'!$A:$C,3,FALSE) -> 0.65934066 | N7: H | O7: =1/2.4/1.03 -> 0.40453074 | P7: Man Utd | Q7: =VLOOKUP($A7,'[1]Outright Odds GW3'!$A:$C,2,FALSE) -> 0.00063449764 | R7: =VLOOKUP($A7,'[1]Outright Odds GW3'!$A:$C,3,FALSE) -> 0.70028011 | S7: =VLOOKUP(P7,'[1]Outright Odds GW3'!$A:$C,2,FALSE) -> 0.028011204 | T7: =VLOOKUP(P7,'[1]Outright Odds GW3'!$A:$C,3,FALSE) -> 0.028011204 | U7: A | V7: =1/8.73/1.03 -> 0.1112112 | W7: Liverpool | X7: =VLOOKUP($A7,'[1]Outright Odds GW4'!$A:$C,2,FALSE) -> 0.00063449764 | Y7: =VLOOKUP($A7,'[1]Outright Odds GW4'!$A:$C,3,FALSE) -> 0.70028011 | Z7: =VLOOKUP(W7,'[1]Outright Odds GW4'!$A:$C,2,FALSE) -> 0.34632035 | AA7: =VLOOKUP(W7,'[1]Outright Odds GW4'!$A:$C,3,FALSE) -> 0.00063449764 | AB7: H | AC7: =1/9.3/1.03 -> 0.10439503
A8: Chelsea | B8: Crystal Palace | C8: =VLOOKUP($A8,'[1]Outright Odds GW1'!$A:$C,2,FALSE) -> 0.095238095 | D8: =VLOOKUP($A8,'[1]Outright Odds GW1'!$A:$C,3,FALSE) -> 0.0047382137 | E8: =VLOOKUP(B8,'[1]Outright Odds GW1'!$A:$C,2,FALSE) -> 0.00190096 | F8: =VLOOKUP(B8,'[1]Outright Odds GW1'!$A:$C,3,FALSE) -> 0.086580087 | G8: H | H8: =1/1.82/1.03 -> 0.53344714 | I8: West Ham | J8: =VLOOKUP($A8,'[1]Outright Odds GW2'!$A:$C,2,FALSE) -> 0.095238095 | K8: =VLOOKUP($A8,'[1]Outright Odds GW2'!$A:$C,3,FALSE) -> 0.0047382137 | L8: =VLOOKUP(I8,'[1]Outright Odds GW2'!$A:$C,2,FALSE) -> 0.00095142952 | M8: =VLOOKUP(I8,'[1]Outright Odds GW2'!$A:$C,3,FALSE) -> 0.14652015 | N8: A | O8: =1/1.74/1.03 -> 0.55797344 | P8: Fulham | Q8: =VLOOKUP($A8,'[1]Outright Odds GW3'!$A:$C,2,FALSE) -> 0.11904762 | R8: =VLOOKUP($A8,'[1]Outright Odds GW3'!$A:$C,3,FALSE) -> 0.00190096 | S8: =VLOOKUP(P8,'[1]Outright Odds GW3'!$A:$C,2,FALSE) -> 0.00095142952 | T8: =VLOOKUP(P8,'[1]Outright Odds GW3'!$A:$C,3,FALSE) -> 0.095238095 | U8: H | V8: =1/1.54/1.03 -> 0.63043752 | W8: Brentford | X8: =VLOOKUP($A8,'[1]Outright Odds GW4'!$A:$C,2,FALSE) -> 0.11904762 | Y8: =VLOOKUP($A8,'[1]Outright Odds GW4'!$A:$C,3,FALSE) -> 0.00190096 | Z8: =VLOOKUP(W8,'[1]Outright Odds GW4'!$A:$C,2,FALSE) -> 0.00095142952 | AA8: =VLOOKUP(W8,'[1]Outright Odds GW4'!$A:$C,3,FALSE) -> 0.25396825 | AB8: A | AC8: =1/1.72/1.03 -> 0.5644615
A9: Crystal Palace | B9: Chelsea | C9: =VLOOKUP($A9,'[1]Outright Odds GW1'!$A:$C,2,FALSE) -> 0.00190096 | D9: =VLOOKUP($A9,'[1]Outright Odds GW1'!$A:$C,3,FALSE) -> 0.086580087 | E9: =VLOOKUP(B9,'[1]Outright Odds GW1'!$A:$C,2,FALSE) -> 0.095238095 | F9: =VLOOKUP(B9,'[1]Outright Odds GW1'!$A:$C,3,FALSE) -> 0.0047382137 | G9: A | H9: =1/4.39/1.03 -> 0.22115576 | I9: Nott'm Forest | J9: =VLOOKUP($A9,'[1]Outright Odds GW2'!$A:$C,2,FALSE) -> 0.00190096 | K9: =VLOOKUP($A9,'[1]Outright Odds GW2'!$A:$C,3,FALSE) -> 0.086580087 | L9: =VLOOKUP(I9,'[1]Outright Odds GW2'!$A:$C,2,FALSE) -> 0.00190096 | M9: =VLOOKUP(I9,'[1]Outright Odds GW2'!$A:$C,3,FALSE) -> 0.086580087 | N9: H | O9: =1/2.39/1.03 -> 0.40622334 | P9: Aston Villa | Q9: =VLOOKUP($A9,'[1]Outright Odds GW3'!$A:$C,2,FALSE) -> 0.00190096 | R9: =VLOOKUP($A9,'[1]Outright Odds GW3'!$A:$C,3,FALSE) -> 0.095238095 | S9: =VLOOKUP(P9,'[1]Outright Odds GW3'!$A:$C,2,FALSE) -> 0.0063071586 | T9: =VLOOKUP(P9,'[1]Outright Odds GW3'!$A:$C,3,FALSE) -> 0.018674136 | U9: A | V9: =1/4.33/1.03 -> 0.22422027 | W9: Sunderland | X9: =VLOOKUP($A9,'[1]Outright Odds GW4'!$A:$C,2,FALSE) -> 0.00190096 | Y9: =VLOOKUP($A9,'[1]Outright Odds GW4'!$A:$C,3,FALSE) -> 0.095238095 | Z9: =VLOOKUP(W9,'[1]Outright Odds GW4'!$A:$C,2,FALSE) -> 0.00063449764 | AA9: =VLOOKUP(W9,'[1]Outright Odds GW4'!$A:$C,3,FALSE) -> 0.60661207 | AB9: H | AC9: =1/1.7/1.03 -> 0.57110223
A10: Everton | B10: Leeds | C10: =VLOOKUP($A10,'[1]Outright Odds GW1'!$A:$C,2,FALSE) -> 0.00190096 | D10: =VLOOKUP($A10,'[1]Outright Odds GW1'!$A:$C,3,FALSE) -> 0.10025063 | E10: =VLOOKUP(B10,'[1]Outright Odds GW1'!$A:$C,2,FALSE) -> 0.00095142952 | F10: =VLOOKUP(B10,'[1]Outright Odds GW1'!$A:$C,3,FALSE) -> 0.3968254 | G10: A | H10: =1/3.14/1.03 -> 0.30919547 | I10: Brighton | J10: =VLOOKUP($A10,'[1]Outright Odds GW2'!$A:$C,2,FALSE) -> 0.00190096 | K10: =VLOOKUP($A10,'[1]Outright Odds GW2'!$A:$C,3,FALSE) -> 0.10025063 | L10: =VLOOKUP(I10,'[1]Outright Odds GW2'!$A:$C,2,FALSE) -> 0.0037943464 | M10: =VLOOKUP(I10,'[1]Outright Odds GW2'!$A:$C,3,FALSE) -> 0.041407867 | N10: H | O10: =1/2.98/1.03 -> 0.32579657 | P10: Wolves | Q10: =VLOOKUP($A10,'[1]Outright Odds GW3'!$A:$C,2,FALSE) -> 0.00190096 | R10: =VLOOKUP($A10,'[1]Outright Odds GW3'!$A:$C,3,FALSE) -> 0.095238095 | S10: =VLOOKUP(P10,'[1]Outright Odds GW3'!$A:$C,2,FALSE) -> 0.00063449764 | T10: =VLOOKUP(P10,'[1]Outright Odds GW3'!$A:$C,3,FALSE) -> 0.38095238 | U10: A | V10: =1/2.94/1.03 -> 0.33022918 | W10: Aston Villa | X10: =VLOOKUP($A10,'[1]Outright Odds GW4'!$A:$C,2,FALSE) -> 0.00190096 | Y10: =VLOOKUP($A10,'[1]Outright Odds GW4'!$A:$C,3,FALSE) -> 0.095238095 | Z10: =VLOOKUP(W10,'[1]Outright Odds GW4'!$A:$C,2,FALSE) -> 0.0063071586 | AA10: =VLOOKUP(W10,'[1]Outright Odds GW4'!$A:$C,3,FALSE) -> 0.018674136 | AB10: H | AC10: =1/3.1/1.03 -> 0.31318509
A11: Fulham | B11: Brighton | C11: =VLOOKUP($A11,'[1]Outright Odds GW1'!$A:$C,2,FALSE) -> 0.00095142952 | D11: =VLOOKUP($A11,'[1]Outright Odds GW1'!$A:$C,3,FALSE) -> 0.073260073 | E11: =VLOOKUP(B11,'[1]Outright Odds GW1'!$A:$C,2,FALSE) -> 0.0037943464 | F11: =VLOOKUP(B11,'[1]Outright Odds GW1'!$A:$C,3,FALSE) -> 0.041407867 | G11: A | H11: =1/4.35/1.03 -> 0.22318938 | I11: Man Utd | J11: =VLOOKUP($A11,'[1]Outright Odds GW2'!$A:$C,2,FALSE) -> 0.00095142952 | K11: =VLOOKUP($A11,'[1]Outright Odds GW2'!$A:$C,3,FALSE) -> 0.073260073 | L11: =VLOOKUP(I11,'[1]Outright Odds GW2'!$A:$C,2,FALSE) -> 0.036630037 | M11: =VLOOKUP(I11,'[1]Outright Odds GW2'!$A:$C,3,FALSE) -> 0.018674136 | N11: H | O11: =1/3.53/1.03 -> 0.27503507 | P11: Chelsea | Q11: =VLOOKUP($A11,'[1]Outright Odds GW3'!$A:$C,2,FALSE) -> 0.00095142952 | R11: =VLOOKUP($A11,'[1]Outright Odds GW3'!$A:$C,3,FALSE) -> 0.095238095 | S11: =VLOOKUP(P11,'[1]Outright Odds GW3'!$A:$C,2,FALSE) -> 0.11904762 | T11: =VLOOKUP(P11,'[1]Outright Odds GW3'!$A:$C,3,FALSE) -> 0.00190096 | U11: A | V11: =1/5.78/1.03 -> 0.16797124 | W11: Leeds | X11: =VLOOKUP($A11,'[1]Outright Odds GW4'!$A:$C,2,FALSE) -> 0.00095142952 | Y11: =VLOOKUP($A11,'[1]Outright Odds GW4'!$A:$C,3,FALSE) -> 0.095238095 | Z11: =VLOOKUP(W11,'[1]Outright Odds GW4'!$A:$C,2,FALSE) -> 0.00190096 | AA11: =VLOOKUP(W11,'[1]Outright Odds GW4'!$A:$C,3,FALSE) -> 0.29304029 | AB11: H | AC11: =1/1.87/1.03 -> 0.51918384
A12: Leeds | B12: Everton | C12: =VLOOKUP($A12,'[1]Outright Odds GW1'!$A:$C,2,FALSE) -> 0.00095142952 | D12: =VLOOKUP($A12,'[1]Outright Odds GW1'!$A:$C,3,FALSE) -> 0.3968254 | E12: =VLOOKUP(B12,'[1]Outright Odds GW1'!$A:$C,2,FALSE) -> 0.00190096 | F12: =VLOOKUP(B12,'[1]Outright Odds GW1'!$A:$C,3,FALSE) -> 0.10025063 | G12: H | H12: =1/2.4/1.03 -> 0.40453074 | I12: Arsenal | J12: =VLOOKUP($A12,'[1]Outright Odds GW2'!$A:$C,2,FALSE) -> 0.00095142952 | K12: =VLOOKUP($A12,'[1]Outright Odds GW2'!$A:$C,3,FALSE) -> 0.3968254 | L12: =VLOOKUP(I12,'[1]Outright Odds GW2'!$A:$C,2,FALSE) -> 0.26092629 | M12: =VLOOKUP(I12,'[1]Outright Odds GW2'!$A:$C,3,FALSE) -> 0.00095142952 | N12: A | O12: =1/8.88/1.03 -> 0.10933263 | P12: Newcastle | Q12: =VLOOKUP($A12,'[1]Outright Odds GW3'!$A:$C,2,FALSE) -> 0.00190096 | R12: =VLOOKUP($A12,'[1]Outright Odds GW3'!$A:$C,3,FALSE) -> 0.29304029 | S12: =VLOOKUP(P12,'[1]Outright Odds GW3'!$A:$C,2,FALSE) -> 0.01175779 | T12: =VLOOKUP(P12,'[1]Outright Odds GW3'!$A:$C,3,FALSE) -> 0.0094295144 | U12: H | V12: =1/3.66/1.03 -> 0.26526606 | W12: Fulham | X12: =VLOOKUP($A12,'[1]Outright Odds GW4'!$A:$C,2,FALSE) -> 0.00190096 | Y12: =VLOOKUP($A12,'[1]Outright Odds GW4'!$A:$C,3,FALSE) -> 0.29304029 | Z12: =VLOOKUP(W12,'[1]Outright Odds GW4'!$A:$C,2,FALSE) -> 0.00095142952 | AA12: =VLOOKUP(W12,'[1]Outright Odds GW4'!$A:$C,3,FALSE) -> 0.095238095 | AB12: A | AC12: =1/4.03/1.03 -> 0.24091161
A13: Liverpool | B13: Bournemouth | C13: =VLOOKUP($A13,'[1]Outright Odds GW1'!$A:$C,2,FALSE) -> 0.32840722 | D13: =VLOOKUP($A13,'[1]Outright Odds GW1'!$A:$C,3,FALSE) -> 0.00095142952 | E13: =VLOOKUP(B13,'[1]Outright Odds GW1'!$A:$C,2,FALSE) -> 0.0012681504 | F13: =VLOOKUP(B13,'[1]Outright Odds GW1'!$A:$C,3,FALSE) -> 0.079365079 | G13: H | H13: =1/1.3/1.03 -> 0.74682599 | I13: Newcastle | J13: =VLOOKUP($A13,'[1]Outright Odds GW2'!$A:$C,2,FALSE) -> 0.32840722 | K13: =VLOOKUP($A13,'[1]Outright Odds GW2'!$A:$C,3,FALSE) -> 0.00095142952 | L13: =VLOOKUP(I13,'[1]Outright Odds GW2'!$A:$C,2,FALSE) -> 0.013413816 | M13: =VLOOKUP(I13,'[1]Outright Odds GW2'!$A:$C,3,FALSE) -> 0.0047382137 | N13: A | O13: =1/2.18/1.03 -> 0.44535495 | P13: Arsenal | Q13: =VLOOKUP($A13,'[1]Outright Odds GW3'!$A:$C,2,FALSE) -> 0.34632035 | R13: =VLOOKUP($A13,'[1]Outright Odds GW3'!$A:$C,3,FALSE) -> 0.00063449764 | S13: =VLOOKUP(P13,'[1]Outright Odds GW3'!$A:$C,2,FALSE) -> 0.34632035 | T13: =VLOOKUP(P13,'[1]Outright Odds GW3'!$A:$C,3,FALSE) -> 0.00095142952 | U13: H | V13: =1/2/1.03 -> 0.48543689 | W13: Burnley | X13: =VLOOKUP($A13,'[1]Outright Odds GW4'!$A:$C,2,FALSE) -> 0.34632035 | Y13: =VLOOKUP($A13,'[1]Outright Odds GW4'!$A:$C,3,FALSE) -> 0.00063449764 | Z13: =VLOOKUP(W13,'[1]Outright Odds GW4'!$A:$C,2,FALSE) -> 0.00063449764 | AA13: =VLOOKUP(W13,'[1]Outright Odds GW4'!$A:$C,3,FALSE) -> 0.70028011 | AB13: A | AC13: =1/1.32/1.03 -> 0.73551044
A14: Man City | B14: Wolves | C14: =VLOOKUP($A14,'[1]Outright Odds GW1'!$A:$C,2,FALSE) -> 0.21164021 | D14: =VLOOKUP($A14,'[1]Outright Odds GW1'!$A:$C,3,FALSE) -> 0.045351474 | E14: =VLOOKUP(B14,'[1]Outright Odds GW1'!$A:$C,2,FALSE) -> 0.00095142952 | F14: =VLOOKUP(B14,'[1]Outright Odds GW1'!$A:$C,3,FALSE) -> 0.21978022 | G14: A | H14: =1/1.53/1.03 -> 0.63455803 | I14: Spurs | J14: =VLOOKUP($A14,'[1]Outright Odds GW2'!$A:$C,2,FALSE) -> 0.21164021 | K14: =VLOOKUP($A14,'[1]Outright Odds GW2'!$A:$C,3,FALSE) -> 0.045351474 | L14: =VLOOKUP(I14,'[1]Outright Odds GW2'!$A:$C,2,FALSE) -> 0.018674136 | M14: =VLOOKUP(I14,'[1]Outright Odds GW2'!$A:$C,3,FALSE) -> 0.0094295144 | N14: H | O14: =1/1.55/1.03 -> 0.62637018 | P14: Brighton | Q14: =VLOOKUP($A14,'[1]Outright Odds GW3'!$A:$C,2,FALSE) -> 0.17316017 | R14: =VLOOKUP($A14,'[1]Outright Odds GW3'!$A:$C,3,FALSE) -> 0.045351474 | S14: =VLOOKUP(P14,'[1]Outright Odds GW3'!$A:$C,2,FALSE) -> 0.00190096 | T14: =VLOOKUP(P14,'[1]Outright Odds GW3'!$A:$C,3,FALSE) -> 0.056022409 | U14: A | V14: =1/1.78/1.03 -> 0.54543471 | W14: Man Utd | X14: =VLOOKUP($A14,'[1]Outright Odds GW4'!$A:$C,2,FALSE) -> 0.17316017 | Y14: =VLOOKUP($A14,'[1]Outright Odds GW4'!$A:$C,3,FALSE) -> 0.045351474 | Z14: =VLOOKUP(W14,'[1]Outright Odds GW4'!$A:$C,2,FALSE) -> 0.028011204 | AA14: =VLOOKUP(W14,'[1]Outright Odds GW4'!$A:$C,3,FALSE) -> 0.028011204 | AB14: H | AC14: =1/1.77/1.03 -> 0.54851626
A15: Man Utd | B15: Arsenal | C15: =VLOOKUP($A15,'[1]Outright Odds GW1'!$A:$C,2,FALSE) -> 0.036630037 | D15: =VLOOKUP($A15,'[1]Outright Odds GW1'!$A:$C,3,FALSE) -> 0.018674136 | E15: =VLOOKUP(B15,'[1]Outright Odds GW1'!$A:$C,2,FALSE) -> 0.26092629 | F15: =VLOOKUP(B15,'[1]Outright Odds GW1'!$A:$C,3,FALSE) -> 0.00095142952 | G15: H | H15: =1/3.81/1.03 -> 0.25482252 | I15: Fulham | J15: =VLOOKUP($A15,'[1]Outright Odds GW2'!$A:$C,2,FALSE) -> 0.036630037 | K15: =VLOOKUP($A15,'[1]Outright Odds GW2'!$A:$C,3,FALSE) -> 0.018674136 | L15: =VLOOKUP(I15,'[1]Outright Odds GW2'!$A:$C,2,FALSE) -> 0.00095142952 | M15: =VLOOKUP(I15,'[1]Outright Odds GW2'!$A:$C,3,FALSE) -> 0.073260073 | N15: A | O15: =1/2.09/1.03 -> 0.46453291 | P15: Burnley | Q15: =VLOOKUP($A15,'[1]Outright Odds GW3'!$A:$C,2,FALSE) -> 0.028011204 | R15: =VLOOKUP($A15,'[1]Outright Odds GW3'!$A:$C,3,FALSE) -> 0.028011204 | S15: =VLOOKUP(P15,'[1]Outright Odds GW3'!$A:$C,2,FALSE) -> 0.00063449764 | T15: =VLOOKUP(P15,'[1]Outright Odds GW3'!$A:$C,3,FALSE) -> 0.70028011 | U15: H | V15: =1/1.35/1.03 -> 0.71916577 | W15: Man City | X15: =VLOOKUP($A15,'[1]Outright Odds GW4'!$A:$C,2,FALSE) -> 0.028011204 | Y15: =VLOOKUP($A15,'[1]Outright Odds GW4'!$A:$C,3,FALSE) -> 0.028011204 | Z15: =VLOOKUP(W15,'[1]Outright Odds GW4'!$A:$C,2,FALSE) -> 0.17316017 | AA15: =VLOOKUP(W15,'[1]Outright Odds GW4'!$A:$C,3,FALSE) -> 0.045351474 | AB15: A | AC15: =1/4.29/1.03 -> 0.22631091
A16: Newcastle | B16: Aston Villa | C16: =VLOOKUP($A16,'[1]Outright Odds GW1'!$A:$C,2,FALSE) -> 0.013413816 | D16: =VLOOKUP($A16,'[1]Outright Odds GW1'!$A:$C,3,FALSE) -> 0.0047382137 | E16: =VLOOKUP(B16,'[1]Outright Odds GW1'!$A:$C,2,FALSE) -> 0.0094295144 | F16: =VLOOKUP(B16,'[1]Outright Odds GW1'!$A:$C,3,FALSE) -> 0.0063071586 | G16: A | H16: =1/2.96/1.03 -> 0.3279979 | I16: Liverpool | J16: =VLOOKUP($A16,'[1]Outright Odds GW2'!$A:$C,2,FALSE) -> 0.013413816 | K16: =VLOOKUP($A16,'[1]Outright Odds GW2'!$A:$C,3,FALSE) -> 0.0047382137 | L16: =VLOOKUP(I16,'[1]Outright Odds GW2'!$A:$C,2,FALSE) -> 0.32840722 | M16: =VLOOKUP(I16,'[1]Outright Odds GW2'!$A:$C,3,FALSE) -> 0.00095142952 | N16: H | O16: =1/3.11/1.03 -> 0.31217807 | P16: Leeds | Q16: =VLOOKUP($A16,'[1]Outright Odds GW3'!$A:$C,2,FALSE) -> 0.01175779 | R16: =VLOOKUP($A16,'[1]Outright Odds GW3'!$A:$C,3,FALSE) -> 0.0094295144 | S16: =VLOOKUP(P16,'[1]Outright Odds GW3'!$A:$C,2,FALSE) -> 0.00190096 | T16: =VLOOKUP(P16,'[1]Outright Odds GW3'!$A:$C,3,FALSE) -> 0.29304029 | U16: A | V16: =1/1.97/1.03 -> 0.49282933 | W16: Wolves | X16: =VLOOKUP($A16,'[1]Outright Odds GW4'!$A:$C,2,FALSE) -> 0.01175779 | Y16: =VLOOKUP($A16,'[1]Outright Odds GW4'!$A:$C,3,FALSE) -> 0.0094295144 | Z16: =VLOOKUP(W16,'[1]Outright Odds GW4'!$A:$C,2,FALSE) -> 0.00063449764 | AA16: =VLOOKUP(W16,'[1]Outright Odds GW4'!$A:$C,3,FALSE) -> 0.38095238 | AB16: H | AC16: =1/1.47/1.03 -> 0.66045836
A17: Nott'm Forest | B17: Brentford | C17: =VLOOKUP($A17,'[1]Outright Odds GW1'!$A:$C,2,FALSE) -> 0.00190096 | D17: =VLOOKUP($A17,'[1]Outright Odds GW1'!$A:$C,3,FALSE) -> 0.086580087 | E17: =VLOOKUP(B17,'[1]Outright Odds GW1'!$A:$C,2,FALSE) -> 0.00095142952 | F17: =VLOOKUP(B17,'[1]Outright Odds GW1'!$A:$C,3,FALSE) -> 0.23809524 | G17: H | H17: =1/1.91/1.03 -> 0.50831088 | I17: Crystal Palace | J17: =VLOOKUP($A17,'[1]Outright Odds GW2'!$A:$C,2,FALSE) -> 0.00190096 | K17: =VLOOKUP($A17,'[1]Outright Odds GW2'!$A:$C,3,FALSE) -> 0.086580087 | L17: =VLOOKUP(I17,'[1]Outright Odds GW2'!$A:$C,2,FALSE) -> 0.00190096 | M17: =VLOOKUP(I17,'[1]Outright Odds GW2'!$A:$C,3,FALSE) -> 0.086580087 | N17: A | O17: =1/3.12/1.03 -> 0.3111775 | P17: West Ham | Q17: =VLOOKUP($A17,'[1]Outright Odds GW3'!$A:$C,2,FALSE) -> 0.0063071586 | R17: =VLOOKUP($A17,'[1]Outright Odds GW3'!$A:$C,3,FALSE) -> 0.086580087 | S17: =VLOOKUP(P17,'[1]Outright Odds GW3'!$A:$C,2,FALSE) -> 0.0004759525 | T17: =VLOOKUP(P17,'[1]Outright Odds GW3'!$A:$C,3,FALSE) -> 0.34632035 | U17: H | V17: =1/1.71/1.03 -> 0.56776245 | W17: Arsenal | X17: =VLOOKUP($A17,'[1]Outright Odds GW4'!$A:$C,2,FALSE) -> 0.0063071586 | Y17: =VLOOKUP($A17,'[1]Outright Odds GW4'!$A:$C,3,FALSE) -> 0.086580087 | Z17: =VLOOKUP(W17,'[1]Outright Odds GW4'!$A:$C,2,FALSE) -> 0.34632035 | AA17: =VLOOKUP(W17,'[1]Outright Odds GW4'!$A:$C,3,FALSE) -> 0.00095142952 | AB17: A | AC17: =1/7.14/1.03 -> 0.13597672
A18: Spurs | B18: Burnley | C18: =VLOOKUP($A18,'[1]Outright Odds GW1'!$A:$C,2,FALSE) -> 0.018674136 | D18: =VLOOKUP($A18,'[1]Outright Odds GW1'!$A:$C,3,FALSE) -> 0.0094295144 | E18: =VLOOKUP(B18,'[1]Outright Odds GW1'!$A:$C,2,FALSE) -> 0.0004759525 | F18: =VLOOKUP(B18,'[1]Outright Odds GW1'!$A:$C,3,FALSE) -> 0.68027211 | G18: H | H18: =1/1.57/1.03 -> 0.61839095 | I18: Man City | J18: =VLOOKUP($A18,'[1]Outright Odds GW2'!$A:$C,2,FALSE) -> 0.018674136 | K18: =VLOOKUP($A18,'[1]Outright Odds GW2'!$A:$C,3,FALSE) -> 0.0094295144 | L18: =VLOOKUP(I18,'[1]Outright Odds GW2'!$A:$C,2,FALSE) -> 0.21164021 | M18: =VLOOKUP(I18,'[1]Outright Odds GW2'!$A:$C,3,FALSE) -> 0.045351474 | N18: A | O18: =1/5.59/1.03 -> 0.17368046 | P18: Bournemouth | Q18: =VLOOKUP($A18,'[1]Outright Odds GW3'!$A:$C,2,FALSE) -> 0.036630037 | R18: =VLOOKUP($A18,'[1]Outright Odds GW3'!$A:$C,3,FALSE) -> 0.0063071586 | S18: =VLOOKUP(P18,'[1]Outright Odds GW3'!$A:$C,2,FALSE) -> 0.00190096 | T18: =VLOOKUP(P18,'[1]Outright Odds GW3'!$A:$C,3,FALSE) -> 0.086580087 | U18: H | V18: =1/1.7/1.03 -> 0.57110223 | W18: West Ham | X18: =VLOOKUP($A18,'[1]Outright Odds GW4'!$A:$C,2,FALSE) -> 0.036630037 | Y18: =VLOOKUP($A18,'[1]Outright Odds GW4'!$A:$C,3,FALSE) -> 0.0063071586 | Z18: =VLOOKUP(W18,'[1]Outright Odds GW4'!$A:$C,2,FALSE) -> 0.0004759525 | AA18: =VLOOKUP(W18,'[1]Outright Odds GW4'!$A:$C,3,FALSE) -> 0.34632035 | AB18: A | AC18: =1/1.91/1.03 -> 0.50831088
A19: Sunderland | B19: West Ham | C19: =VLOOKUP($A19,'[1]Outright Odds GW1'!$A:$C,2,FALSE) -> 0.0004759525 | D19: =VLOOKUP($A19,'[1]Outright Odds GW1'!$A:$C,3,FALSE) -> 0.65934066 | E19: =VLOOKUP(B19,'[1]Outright Odds GW1'!$A:$C,2,FALSE) -> 0.00095142952 | F19: =VLOOKUP(B19,'[1]Outright Odds GW1'!$A:$C,3,FALSE) -> 0.14652015 | G19: H | H19: =1/3.46/1.03 -> 0.28059936 | I19: Burnley | J19: =VLOOKUP($A19,'[1]Outright Odds GW2'!$A:$C,2,FALSE) -> 0.0004759525 | K19: =VLOOKUP($A19,'[1]Outright Odds GW2'!$A:$C,3,FALSE) -> 0.65934066 | L19: =VLOOKUP(I19,'[1]Outright Odds GW2'!$A:$C,2,FALSE) -> 0.0004759525 | M19: =VLOOKUP(I19,'[1]Outright Odds GW2'!$A:$C,3,FALSE) -> 0.68027211 | N19: A | O19: =1/3.21/1.03 -> 0.30245289 | P19: Brentford | Q19: =VLOOKUP($A19,'[1]Outright Odds GW3'!$A:$C,2,FALSE) -> 0.00063449764 | R19: =VLOOKUP($A19,'[1]Outright Odds GW3'!$A:$C,3,FALSE) -> 0.60661207 | S19: =VLOOKUP(P19,'[1]Outright Odds GW3'!$A:$C,2,FALSE) -> 0.00095142952 | T19: =VLOOKUP(P19,'[1]Outright Odds GW3'!$A:$C,3,FALSE) -> 0.25396825 | U19: H | V19: =1/2.67/1.03 -> 0.36362314 | W19: Crystal Palace | X19: =VLOOKUP($A19,'[1]Outright Odds GW4'!$A:$C,2,FALSE) -> 0.00063449764 | Y19: =VLOOKUP($A19,'[1]Outright Odds GW4'!$A:$C,3,FALSE) -> 0.60661207 | Z19: =VLOOKUP(W19,'[1]Outright Odds GW4'!$A:$C,2,FALSE) -> 0.00190096 | AA19: =VLOOKUP(W19,'[1]Outright Odds GW4'!$A:$C,3,FALSE) -> 0.095238095 | AB19: A | AC19: =1/4.89/1.03 -> 0.1985427
A20: West Ham | B20: Sunderland | C20: =VLOOKUP($A20,'[1]Outright Odds GW1'!$A:$C,2,FALSE) -> 0.00095142952 | D20: =VLOOKUP($A20,'[1]Outright Odds GW1'!$A:$C,3,FALSE) -> 0.14652015 | E20: =VLOOKUP(B20,'[1]Outright Odds GW1'!$A:$C,2,FALSE) -> 0.0004759525 | F20: =VLOOKUP(B20,'[1]Outright Odds GW1'!$A:$C,3,FALSE) -> 0.65934066 | G20: A | H20: =1/2.25/1.03 -> 0.43149946 | I20: Chelsea | J20: =VLOOKUP($A20,'[1]Outright Odds GW2'!$A:$C,2,FALSE) -> 0.00095142952 | K20: =VLOOKUP($A20,'[1]Outright Odds GW2'!$A:$C,3,FALSE) -> 0.14652015 | L20: =VLOOKUP(I20,'[1]Outright Odds GW2'!$A:$C,2,FALSE) -> 0.095238095 | M20: =VLOOKUP(I20,'[1]Outright Odds GW2'!$A:$C,3,FALSE) -> 0.0047382137 | N20: H | O20: =1/4.72/1.03 -> 0.2056936 | P20: Nott'm Forest | Q20: =VLOOKUP($A20,'[1]Outright Odds GW3'!$A:$C,2,FALSE) -> 0.0004759525 | R20: =VLOOKUP($A20,'[1]Outright Odds GW3'!$A:$C,3,FALSE) -> 0.34632035 | S20: =VLOOKUP(P20,'[1]Outright Odds GW3'!$A:$C,2,FALSE) -> 0.0063071586 | T20: =VLOOKUP(P20,'[1]Outright Odds GW3'!$A:$C,3,FALSE) -> 0.086580087 | U20: A | V20: =1/5.02/1.03 -> 0.19340115 | W20: Spurs | X20: =VLOOKUP($A20,'[1]Outright Odds GW4'!$A:$C,2,FALSE) -> 0.0004759525 | Y20: =VLOOKUP($A20,'[1]Outright Odds GW4'!$A:$C,3,FALSE) -> 0.34632035 | Z20: =VLOOKUP(W20,'[1]Outright Odds GW4'!$A:$C,2,FALSE) -> 0.036630037 | AA20: =VLOOKUP(W20,'[1]Outright Odds GW4'!$A:$C,3,FALSE) -> 0.0063071586 | AB20: H | AC20: =1/3.86/1.03 -> 0.25152171
A21: Wolves | B21: Man City | C21: =VLOOKUP($A21,'[1]Outright Odds GW1'!$A:$C,2,FALSE) -> 0.00095142952 | D21: =VLOOKUP($A21,'[1]Outright Odds GW1'!$A:$C,3,FALSE) -> 0.21978022 | E21: =VLOOKUP(B21,'[1]Outright Odds GW1'!$A:$C,2,FALSE) -> 0.21164021 | F21: =VLOOKUP(B21,'[1]Outright Odds GW1'!$A:$C,3,FALSE) -> 0.045351474 | G21: H | H21: =1/6.33/1.03 -> 0.15337659 | I21: Bournemouth | J21: =VLOOKUP($A21,'[1]Outright Odds GW2'!$A:$C,2,FALSE) -> 0.00095142952 | K21: =VLOOKUP($A21,'[1]Outright Odds GW2'!$A:$C,3,FALSE) -> 0.21978022 | L21: =VLOOKUP(I21,'[1]Outright Odds GW2'!$A:$C,2,FALSE) -> 0.0012681504 | M21: =VLOOKUP(I21,'[1]Outright Odds GW2'!$A:$C,3,FALSE) -> 0.079365079 | N21: A | O21: =1/4.44/1.03 -> 0.21866527 | P21: Everton | Q21: =VLOOKUP($A21,'[1]Outright Odds GW3'!$A:$C,2,FALSE) -> 0.00063449764 | R21: =VLOOKUP($A21,'[1]Outright Odds GW3'!$A:$C,3,FALSE) -> 0.38095238 | S21: =VLOOKUP(P21,'[1]Outright Odds GW3'!$A:$C,2,FALSE) -> 0.00190096 | T21: =VLOOKUP(P21,'[1]Outright Odds GW3'!$A:$C,3,FALSE) -> 0.095238095 | U21: H | V21: =1/2.47/1.03 -> 0.39306631 | W21: Newcastle | X21: =VLOOKUP($A21,'[1]Outright Odds GW4'!$A:$C,2,FALSE) -> 0.00063449764 | Y21: =VLOOKUP($A21,'[1]Outright Odds GW4'!$A:$C,3,FALSE) -> 0.38095238 | Z21: =VLOOKUP(W21,'[1]Outright Odds GW4'!$A:$C,2,FALSE) -> 0.01175779 | AA21: =VLOOKUP(W21,'[1]Outright Odds GW4'!$A:$C,3,FALSE) -> 0.0094295144 | AB21: A | AC21: =1/6.51/1.03 -> 0.14913576
